Workbook
Name BĐ: 'List+TK'!$AB$27:$AB$46
Name BT: 'List+TK'!$AB$3:$AB$26
Name CL: 'List+TK'!$AB$69:$AB$79
Name Coso: CS!$B$3:$B$101
Name CT: 'List+TK'!$AB$47:$AB$68
Name Chitieu: 'List+TK'!$D$3:$D$72
Name Ghichu: 'List+TK'!$K$3:$K$5
Name GT: 'List+TK'!$AB$80:$AB$101
Name Huyen: 'List+TK'!$Y$3:$Y$11
Name MCB: 'List+TK'!$AB$102:$AB$114
Name MCN: 'List+TK'!$AB$115:$AB$131
Name Nguoilay: 'List+TK'!$G$3:$G$13
Name Tenmau: 'List+TK'!$C$3:$C$15
Name TP: 'List+TK'!$AB$132:$AB$149
Name TPBT: 'List+TK'!$AB$150:$AB$166

Sheet Thuysan
I2: =SUBTOTAL(3,I4:I343) -> 169 | J2: =SUBTOTAL(3,J4:J343) -> 169 | S2: =SUBTOTAL(9,S4:S172) -> 216 | T2: =SUBTOTAL(3,T4:T343) -> 169 | X2: =SUBTOTAL(3,X4:X343) -> 6
A3: STT | B3: STT | C3: Tên cơ sở | D3: Khu nuôi, ấp | E3: Xã/Phường/TT | F3: Huyện | G3: Tháng | H3: Ngày | I3: Tên mẫu | J3: Chỉ tiêu | K3: Người lấy | L3: Tên vùng nuôi | M3: Mã số | N3: Ao | O3: Tên mẫu | P3: Mã số mẫu | Q3: Vùng nuôi | R3: Cơ sở lấy mẫu | S3: Kg | T3: Chỉ tiêu | U3: Thời gian | V3: Người lấy mẫu | W3: Ao | X3: Ghi chú
A4: =_xlfn.AGGREGATE(3,3,$I$4:I4) -> 1 | B4: 1 | C4: Công ty CP Gò Đàng | D4: Ấp 4 | E4: Xã Tân Xuân | F4: Huyện Ba Tri | G4: 2 | H4: 27 | I4: Cá tra thương phẩm | J4: CV+LCV | K4: Thuận | L4: =IFERROR(IF(F4="Huyện Mỏ Cày Nam","Mỏ Cày",RIGHT(F4,LEN(F4)-6)),"-") -> Ba Tri | M4: =IFERROR(VLOOKUP(L4,'List+TK'!$I$3:$J$9,2,0),"-") -> 83/01 | N4: A2 | O4: =I4 -> Cá tra thương phẩm | P4: ="83/"&IF(LEN(G4)=1,"0"&G4,G4)&"24/"&IF(LEN(B4)=1,"0"&B4,B4) -> 83/0224/01 | Q4: =L4&" "&M4 -> Ba Tri 83/01 | R4: =C4&" - "&D4&", "&E4 -> Công ty CP Gò Đàng - Ấp 4, Xã Tân Xuân | S4: =IF(OR(I4="Tôm chân trắng nhỏ",I4="Tôm sú nhỏ"),0.5,IF(OR(I4="Cá tra nhỏ",I4="Tôm sú thương phẩm",I4="Tôm chân trắng thương phẩm",I4="Tôm sú quảng canh",I4="Nước ương tôm giống"),1,IF(I4="Cá tra thương phẩm",1.5,0))) -> 1.5 | T4: =IFERROR(VLOOKUP(J4,'List+TK'!$D$3:$E$1000,2,0),"-") -> Crystal Violet, Leuco Crystal Violet | U4: =H4&"/"&IF(LEN(G4)=1,"0"&G4,G4)&"/2024" -> 27/02/2024 | V4: =IFERROR(VLOOKUP(K4,'List+TK'!$G$3:$H$16,2,0),"-") -> Phạm Minh Thuận | W4: =IF(N4="","",IF(I4="Nước ương tôm giống","Bể "&N4,"Ao "&N4)) -> Ao A2
A5: =_xlfn.AGGREGATE(3,3,$I$4:I5) -> 2 | B5: 2 | C5: Công ty TNHH Thực Phẩm Vạn Đức | D5: Ấp 6 | E5: Xã Bảo Thạnh | F5: Huyện Ba Tri | G5: 2 | H5: 27 | I5: Cá chẽm nhỏ | J5: A1c | K5: Thuận | L5: =IFERROR(IF(F5="Huyện Mỏ Cày Nam","Mỏ Cày",RIGHT(F5,LEN(F5)-6)),"-") -> Ba Tri | M5: =IFERROR(VLOOKUP(L5,'List+TK'!$I$3:$J$9,2,0),"-") -> 83/01 | N5: B10 | O5: =I5 -> Cá chẽm nhỏ | P5: ="83/"&IF(LEN(G5)=1,"0"&G5,G5)&"24/"&IF(LEN(B5)=1,"0"&B5,B5) -> 83/0224/02 | Q5: =L5&" "&M5 -> Ba Tri 83/01 | R5: =C5&" - "&D5&", "&E5 -> Công ty TNHH Thực Phẩm Vạn Đức - Ấp 6, Xã Bảo Thạnh | S5: 1 | T5: =IFERROR(VLOOKUP(J5,'List+TK'!$D$3:$E$1000,2,0),"-") -> Methyltestosterone | U5: =H5&"/"&IF(LEN(G5)=1,"0"&G5,G5)&"/2024" -> 27/02/2024 | V5: =IFERROR(VLOOKUP(K5,'List+TK'!$G$3:$H$16,2,0),"-") -> Phạm Minh Thuận | W5: =IF(N5="","",IF(I5="Nước ương tôm giống","Bể "&N5,"Ao "&N5)) -> Ao B10
A6: =_xlfn.AGGREGATE(3,3,$I$4:I6) -> 3 | B6: 3 | C6: Công ty TNHH Thực Phẩm Vạn Đức | D6: Ấp 6 | E6: Xã Bảo Thạnh | F6: Huyện Ba Tri | G6: 2 | H6: 27 | I6: Cá chẽm thương phẩm | J6: KLN | K6: Thuận | L6: =IFERROR(IF(F6="Huyện Mỏ Cày Nam","Mỏ Cày",RIGHT(F6,LEN(F6)-6)),"-") -> Ba Tri | M6: =IFERROR(VLOOKUP(L6,'List+TK'!$I$3:$J$9,2,0),"-") -> 83/01 | N6: 6 | O6: =I6 -> Cá chẽm thương phẩm | P6: ="83/"&IF(LEN(G6)=1,"0"&G6,G6)&"24/"&IF(LEN(B6)=1,"0"&B6,B6) -> 83/0224/03 | Q6: =L6&" "&M6 -> Ba Tri 83/01 | R6: =C6&" - "&D6&", "&E6 -> Công ty TNHH Thực Phẩm Vạn Đức - Ấp 6, Xã Bảo Thạnh | S6: 1.5 | T6: =IFERROR(VLOOKUP(J6,'List+TK'!$D$3:$E$1000,2,0),"-") -> Pb, Hg, Cd | U6: =H6&"/"&IF(LEN(G6)=1,"0"&G6,G6)&"/2024" -> 27/02/2024 | V6: =IFERROR(VLOOKUP(K6,'List+TK'!$G$3:$H$16,2,0),"-") -> Phạm Minh Thuận | W6: =IF(N6="","",IF(I6="Nước ương tôm giống","Bể "&N6,"Ao "&N6)) -> Ao 6
A7: =_xlfn.AGGREGATE(3,3,$I$4:I7) -> 4 | B7: 4 | C7: Cao Văn Dước | D7: Ấp 3 | E7: Xã Phú Vang | F7: Huyện Bình Đại | G7: 2 | H7: 27 | I7: Tôm chân trắng nhỏ | J7: Nitroi | K7: Nguyên | L7: =IFERROR(IF(F7="Huyện Mỏ Cày Nam","Mỏ Cày",RIGHT(F7,LEN(F7)-6)),"-") -> Bình Đại | M7: =IFERROR(VLOOKUP(L7,'List+TK'!$I$3:$J$9,2,0),"-") -> 83/02 | N7: 1 | O7: =I7 -> Tôm chân trắng nhỏ | P7: ="83/"&IF(LEN(G7)=1,"0"&G7,G7)&"24/"&IF(LEN(B7)=1,"0"&B7,B7) -> 83/0224/04 | Q7: =L7&" "&M7 -> Bình Đại 83/02 | R7: =C7&" - "&D7&", "&E7 -> Cao Văn Dước - Ấp 3, Xã Phú Vang | S7: =IF(OR(I7="Tôm chân trắng nhỏ",I7="Tôm sú nhỏ"),0.5,IF(OR(I7="Cá tra nhỏ",I7="Tôm sú thương phẩm",I7="Tôm chân trắng thương phẩm",I7="Tôm sú quảng canh",I7="Nước ương tôm giống"),1,IF(I7="Cá tra thương phẩm",1.5,0))) -> 0.5 | T7: =IFERROR(VLOOKUP(J7,'List+TK'!$D$3:$E$1000,2,0),"-") -> Nhóm Nitroimidazoles | U7: =H7&"/"&IF(LEN(G7)=1,"0"&G7,G7)&"/2024" -> 27/02/2024 | V7: =IFERROR(VLOOKUP(K7,'List+TK'!$G$3:$H$16,2,0),"-") -> Cao Quang Nguyên | W7: =IF(N7="","",IF(I7="Nước ương tôm giống","Bể "&N7,"Ao "&N7)) -> Ao 1
A8: =_xlfn.AGGREGATE(3,3,$I$4:I8) -> 5 | B8: 5 | C8: Công ty CP Thủy sản Vinh Quang | D8: Ấp Hưng Thạnh | E8: Xã Châu Hưng | F8: Huyện Bình Đại | G8: 2 | H8: 27 | I8: Cá tra nhỏ | J8: A1c | K8: Nguyên | L8: =IFERROR(IF(F8="Huyện Mỏ Cày Nam","Mỏ Cày",RIGHT(F8,LEN(F8)-6)),"-") -> Bình Đại | M8: =IFERROR(VLOOKUP(L8,'List+TK'!$I$3:$J$9,2,0),"-") -> 83/02 | N8: 1 | O8: =I8 -> Cá tra nhỏ | P8: ="83/"&IF(LEN(G8)=1,"0"&G8,G8)&"24/"&IF(LEN(B8)=1,"0"&B8,B8) -> 83/0224/05 | Q8: =L8&" "&M8 -> Bình Đại 83/02 | R8: =C8&" - "&D8&", "&E8 -> Công ty CP Thủy sản Vinh Quang - Ấp Hưng Thạnh, Xã Châu Hưng | S8: =IF(OR(I8="Tôm chân trắng nhỏ",I8="Tôm sú nhỏ"),0.5,IF(OR(I8="Cá tra nhỏ",I8="Tôm sú thương phẩm",I8="Tôm chân trắng thương phẩm",I8="Tôm sú quảng canh",I8="Nước ương tôm giống"),1,IF(I8="Cá tra thương phẩm",1.5,0))) -> 1 | T8: =IFERROR(VLOOKUP(J8,'List+TK'!$D$3:$E$1000,2,0),"-") -> Methyltestosterone | U8: =H8&"/"&IF(LEN(G8)=1,"0"&G8,G8)&"/2024" -> 27/02/2024 | V8: =IFERROR(VLOOKUP(K8,'List+TK'!$G$3:$H$16,2,0),"-") -> Cao Quang Nguyên | W8: =IF(N8="","",IF(I8="Nước ương tôm giống","Bể "&N8,"Ao "&N8)) -> Ao 1
A9: =_xlfn.AGGREGATE(3,3,$I$4:I9) -> 6 | B9: 6 | C9: Cao Văn Tùng | D9: Ấp An Hòa | E9: Xã An Nhơn | F9: Huyện Thạnh Phú | G9: 2 | H9: 28 | I9: Tôm chân trắng nhỏ | J9: CAP | K9: Nguyên | L9: =IFERROR(IF(F9="Huyện Mỏ Cày Nam","Mỏ Cày",RIGHT(F9,LEN(F9)-6)),"-") -> Thạnh Phú | M9: =IFERROR(VLOOKUP(L9,'List+TK'!$I$3:$J$9,2,0),"-") -> 83/03 | N9: 1 | O9: =I9 -> Tôm chân trắng nhỏ | P9: ="83/"&IF(LEN(G9)=1,"0"&G9,G9)&"24/"&IF(LEN(B9)=1,"0"&B9,B9) -> 83/0224/06 | Q9: =L9&" "&M9 -> Thạnh Phú 83/03 | R9: =C9&" - "&D9&", "&E9 -> Cao Văn Tùng - Ấp An Hòa, Xã An Nhơn | S9: =IF(OR(I9="Tôm chân trắng nhỏ",I9="Tôm sú nhỏ"),0.5,IF(OR(I9="Cá tra nhỏ",I9="Tôm sú thương phẩm",I9="Tôm chân trắng thương phẩm",I9="Tôm sú quảng canh",I9="Nước ương tôm giống"),1,IF(I9="Cá tra thương phẩm",1.5,0))) -> 0.5 | T9: =IFERROR(VLOOKUP(J9,'List+TK'!$D$3:$E$1000,2,0),"-") -> Chloramphenicol | U9: =H9&"/"&IF(LEN(G9)=1,"0"&G9,G9)&"/2024" -> 28/02/2024 | V9: =IFERROR(VLOOKUP(K9,'List+TK'!$G$3:$H$16,2,0),"-") -> Cao Quang Nguyên | W9: =IF(N9="","",IF(I9="Nước ương tôm giống","Bể "&N9,"Ao "&N9)) -> Ao 1
A10: =_xlfn.AGGREGATE(3,3,$I$4:I10) -> 7 | B10: 7 | C10: Công ty CP Gò Đàng | D10: Ấp Phú Luông | E10: Xã Tân Phú | F10: Huyện Châu Thành | G10: 2 | H10: 27 | I10: Cá tra nhỏ | J10: A1c | K10: Khanh | L10: =IFERROR(IF(F10="Huyện Mỏ Cày Nam","Mỏ Cày",RIGHT(F10,LEN(F10)-6)),"-") -> Châu Thành | M10: =IFERROR(VLOOKUP(L10,'List+TK'!$I$3:$J$9,2,0),"-") -> 83/05 | N10: 3 | O10: =I10 -> Cá tra nhỏ | P10: ="83/"&IF(LEN(G10)=1,"0"&G10,G10)&"24/"&IF(LEN(B10)=1,"0"&B10,B10) -> 83/0224/07 | Q10: =L10&" "&M10 -> Châu Thành 83/05 | R10: =C10&" - "&D10&", "&E10 -> Công ty CP Gò Đàng - Ấp Phú Luông, Xã Tân Phú | S10: =IF(OR(I10="Tôm chân trắng nhỏ",I10="Tôm sú nhỏ"),0.5,IF(OR(I10="Cá tra nhỏ",I10="Tôm sú thương phẩm",I10="Tôm chân trắng thương phẩm",I10="Tôm sú quảng canh",I10="Nước ương tôm giống"),1,IF(I10="Cá tra thương phẩm",1.5,0))) -> 1 | T10: =IFERROR(VLOOKUP(J10,'List+TK'!$D$3:$E$1000,2,0),"-") -> Methyltestosterone | U10: =H10&"/"&IF(LEN(G10)=1,"0"&G10,G10)&"/2024" -> 27/02/2024 | V10: =IFERROR(VLOOKUP(K10,'List+TK'!$G$3:$H$16,2,0),"-") -> Nguyễn Duy Khanh | W10: =IF(N10="","",IF(I10="Nước ương tôm giống","Bể "&N10,"Ao "&N10)) -> Ao 3
A11: =_xlfn.AGGREGATE(3,3,$I$4:I11) -> 8 | B11: 8 | C11: Công ty CP Gò Đàng | D11: Ấp Phú Luông | E11: Xã Tân Phú | F11: Huyện Châu Thành | G11: 2 | H11: 27 | I11: Cá tra nhỏ | J11: Nitroi | K11: Khanh | L11: =IFERROR(IF(F11="Huyện Mỏ Cày Nam","Mỏ Cày",RIGHT(F11,LEN(F11)-6)),"-") -> Châu Thành | M11: =IFERROR(VLOOKUP(L11,'List+TK'!$I$3:$J$9,2,0),"-") -> 83/05 | N11: 4 | O11: =I11 -> Cá tra nhỏ | P11: ="83/"&IF(LEN(G11)=1,"0"&G11,G11)&"24/"&IF(LEN(B11)=1,"0"&B11,B11) -> 83/0224/08 | Q11: =L11&" "&M11 -> Châu Thành 83/05 | R11: =C11&" - "&D11&", "&E11 -> Công ty CP Gò Đàng - Ấp Phú Luông, Xã Tân Phú | S11: =IF(OR(I11="Tôm chân trắng nhỏ",I11="Tôm sú nhỏ"),0.5,IF(OR(I11="Cá tra nhỏ",I11="Tôm sú thương phẩm",I11="Tôm chân trắng thương phẩm",I11="Tôm sú quảng canh",I11="Nước ương tôm giống"),1,IF(I11="Cá tra thương phẩm",1.5,0))) -> 1 | T11: =IFERROR(VLOOKUP(J11,'List+TK'!$D$3:$E$1000,2,0),"-") -> Nhóm Nitroimidazoles | U11: =H11&"/"&IF(LEN(G11)=1,"0"&G11,G11)&"/2024" -> 27/02/2024 | V11: =IFERROR(VLOOKUP(K11,'List+TK'!$G$3:$H$16,2,0),"-") -> Nguyễn Duy Khanh | W11: =IF(N11="","",IF(I11="Nước ương tôm giống","Bể "&N11,"Ao "&N11)) -> Ao 4
A12: =_xlfn.AGGREGATE(3,3,$I$4:I12) -> 9 | B12: 9 | C12: Công ty CP Gò Đàng | D12: Ấp Phú Luông | E12: Xã Tân Phú | F12: Huyện Châu Thành | G12: 2 | H12: 27 | I12: Cá tra nhỏ | J12: KLN | K12: Khanh | L12: =IFERROR(IF(F12="Huyện Mỏ Cày Nam","Mỏ Cày",RIGHT(F12,LEN(F12)-6)),"-") -> Châu Thành | M12: =IFERROR(VLOOKUP(L12,'List+TK'!$I$3:$J$9,2,0),"-") -> 83/05 | N12: 5 | O12: =I12 -> Cá tra nhỏ | P12: ="83/"&IF(LEN(G12)=1,"0"&G12,G12)&"24/"&IF(LEN(B12)=1,"0"&B12,B12) -> 83/0224/09 | Q12: =L12&" "&M12 -> Châu Thành 83/05 | R12: =C12&" - "&D12&", "&E12 -> Công ty CP Gò Đàng - Ấp Phú Luông, Xã Tân Phú | S12: =IF(OR(I12="Tôm chân trắng nhỏ",I12="Tôm sú nhỏ"),0.5,IF(OR(I12="Cá tra nhỏ",I12="Tôm sú thương phẩm",I12="Tôm chân trắng thương phẩm",I12="Tôm sú quảng canh",I12="Nước ương tôm giống"),1,IF(I12="Cá tra thương phẩm",1.5,0))) -> 1 | T12: =IFERROR(VLOOKUP(J12,'List+TK'!$D$3:$E$1000,2,0),"-") -> Pb, Hg, Cd | U12: =H12&"/"&IF(LEN(G12)=1,"0"&G12,G12)&"/2024" -> 27/02/2024 | V12: =IFERROR(VLOOKUP(K12,'List+TK'!$G$3:$H$16,2,0),"-") -> Nguyễn Duy Khanh | W12: =IF(N12="","",IF(I12="Nước ương tôm giống","Bể "&N12,"Ao "&N12)) -> Ao 5
A13: =_xlfn.AGGREGATE(3,3,$I$4:I13) -> 10 | B13: 10 | C13: Công ty CP Gò Đàng | D13: Ấp 1 | E13: Xã Sơn Phú | F13: Huyện Giồng Trôm | G13: 2 | H13: 28 | I13: Cá tra nhỏ | J13: A1c | K13: Thuận | L13: =IFERROR(IF(F13="Huyện Mỏ Cày Nam","Mỏ Cày",RIGHT(F13,LEN(F13)-6)),"-") -> Giồng Trôm | M13: =IFERROR(VLOOKUP(L13,'List+TK'!$I$3:$J$9,2,0),"-") -> 83/06 | N13: 2 | O13: =I13 -> Cá tra nhỏ | P13: ="83/"&IF(LEN(G13)=1,"0"&G13,G13)&"24/"&IF(LEN(B13)=1,"0"&B13,B13) -> 83/0224/10 | Q13: =L13&" "&M13 -> Giồng Trôm 83/06 | R13: =C13&" - "&D13&", "&E13 -> Công ty CP Gò Đàng - Ấp 1, Xã Sơn Phú | S13: =IF(OR(I13="Tôm chân trắng nhỏ",I13="Tôm sú nhỏ"),0.5,IF(OR(I13="Cá tra nhỏ",I13="Tôm sú thương phẩm",I13="Tôm chân trắng thương phẩm",I13="Tôm sú quảng canh",I13="Nước ương tôm giống"),1,IF(I13="Cá tra thương phẩm",1.5,0))) -> 1 | T13: =IFERROR(VLOOKUP(J13,'List+TK'!$D$3:$E$1000,2,0),"-") -> Methyltestosterone | U13: =H13&"/"&IF(LEN(G13)=1,"0"&G13,G13)&"/2024" -> 28/02/2024 | V13: =IFERROR(VLOOKUP(K13,'List+TK'!$G$3:$H$16,2,0),"-") -> Phạm Minh Thuận | W13: =IF(N13="","",IF(I13="Nước ương tôm giống","Bể "&N13,"Ao "&N13)) -> Ao 2
A14: =_xlfn.AGGREGATE(3,3,$I$4:I14) -> 11 | B14: 11 | C14: Công ty CP Gò Đàng | D14: Ấp 1 | E14: Xã Sơn Phú | F14: Huyện Giồng Trôm | G14: 2 | H14: 28 | I14: Cá tra thương phẩm | J14: CAP | K14: Thuận | L14: =IFERROR(IF(F14="Huyện Mỏ Cày Nam","Mỏ Cày",RIGHT(F14,LEN(F14)-6)),"-") -> Giồng Trôm | M14: =IFERROR(VLOOKUP(L14,'List+TK'!$I$3:$J$9,2,0),"-") -> 83/06 | N14: 3 | O14: =I14 -> Cá tra thương phẩm | P14: ="83/"&IF(LEN(G14)=1,"0"&G14,G14)&"24/"&IF(LEN(B14)=1,"0"&B14,B14) -> 83/0224/11 | Q14: =L14&" "&M14 -> Giồng Trôm 83/06 | R14: =C14&" - "&D14&", "&E14 -> Công ty CP Gò Đàng - Ấp 1, Xã Sơn Phú | S14: =IF(OR(I14="Tôm chân trắng nhỏ",I14="Tôm sú nhỏ"),0.5,IF(OR(I14="Cá tra nhỏ",I14="Tôm sú thương phẩm",I14="Tôm chân trắng thương phẩm",I14="Tôm sú quảng canh",I14="Nước ương tôm giống"),1,IF(I14="Cá tra thương phẩm",1.5,0))) -> 1.5 | T14: =IFERROR(VLOOKUP(J14,'List+TK'!$D$3:$E$1000,2,0),"-") -> Chloramphenicol | U14: =H14&"/"&IF(LEN(G14)=1,"0"&G14,G14)&"/2024" -> 28/02/2024 | V14: =IFERROR(VLOOKUP(K14,'List+TK'!$G$3:$H$16,2,0),"-") -> Phạm Minh Thuận | W14: =IF(N14="","",IF(I14="Nước ương tôm giống","Bể "&N14,"Ao "&N14)) -> Ao 3
A15: =_xlfn.AGGREGATE(3,3,$I$4:I15) -> 12 | B15: 12 | C15: Công ty CP Gò Đàng | D15: Ấp 1 | E15: Xã Sơn Phú | F15: Huyện Giồng Trôm | G15: 2 | H15: 28 | I15: Cá tra thương phẩm | J15: NF | K15: Thuận | L15: =IFERROR(IF(F15="Huyện Mỏ Cày Nam","Mỏ Cày",RIGHT(F15,LEN(F15)-6)),"-") -> Giồng Trôm | M15: =IFERROR(VLOOKUP(L15,'List+TK'!$I$3:$J$9,2,0),"-") -> 83/06 | N15: 5 | O15: =I15 -> Cá tra thương phẩm | P15: ="83/"&IF(LEN(G15)=1,"0"&G15,G15)&"24/"&IF(LEN(B15)=1,"0"&B15,B15) -> 83/0224/12 | Q15: =L15&" "&M15 -> Giồng Trôm 83/06 | R15: =C15&" - "&D15&", "&E15 -> Công ty CP Gò Đàng - Ấp 1, Xã Sơn Phú | S15: =IF(OR(I15="Tôm chân trắng nhỏ",I15="Tôm sú nhỏ"),0.5,IF(OR(I15="Cá tra nhỏ",I15="Tôm sú thương phẩm",I15="Tôm chân trắng thương phẩm",I15="Tôm sú quảng canh",I15="Nước ương tôm giống"),1,IF(I15="Cá tra thương phẩm",1.5,0))) -> 1.5 | T15: =IFERROR(VLOOKUP(J15,'List+TK'!$D$3:$E$1000,2,0),"-") -> Nitrofurans | U15: =H15&"/"&IF(LEN(G15)=1,"0"&G15,G15)&"/2024" -> 28/02/2024 | V15: =IFERROR(VLOOKUP(K15,'List+TK'!$G$3:$H$16,2,0),"-") -> Phạm Minh Thuận | W15: =IF(N15="","",IF(I15="Nước ương tôm giống","Bể "&N15,"Ao "&N15)) -> Ao 5
A16: =_xlfn.AGGREGATE(3,3,$I$4:I16) -> 13 | B16: 13 | C16: Công ty CP Gò Đàng | D16: Ấp 1 | E16: Xã Sơn Phú | F16: Huyện Giồng Trôm | G16: 2 | H16: 28 | I16: Cá tra thương phẩm | J16: Nitroi | K16: Thuận | L16: =IFERROR(IF(F16="Huyện Mỏ Cày Nam","Mỏ Cày",RIGHT(F16,LEN(F16)-6)),"-") -> Giồng Trôm | M16: =IFERROR(VLOOKUP(L16,'List+TK'!$I$3:$J$9,2,0),"-") -> 83/06 | N16: 6 | O16: =I16 -> Cá tra thương phẩm | P16: ="83/"&IF(LEN(G16)=1,"0"&G16,G16)&"24/"&IF(LEN(B16)=1,"0"&B16,B16) -> 83/0224/13 | Q16: =L16&" "&M16 -> Giồng Trôm 83/06 | R16: =C16&" - "&D16&", "&E16 -> Công ty CP Gò Đàng - Ấp 1, Xã Sơn Phú | S16: =IF(OR(I16="Tôm chân trắng nhỏ",I16="Tôm sú nhỏ"),0.5,IF(OR(I16="Cá tra nhỏ",I16="Tôm sú thương phẩm",I16="Tôm chân trắng thương phẩm",I16="Tôm sú quảng canh",I16="Nước ương tôm giống"),1,IF(I16="Cá tra thương phẩm",1.5,0))) -> 1.5 | T16: =IFERROR(VLOOKUP(J16,'List+TK'!$D$3:$E$1000,2,0),"-") -> Nhóm Nitroimidazoles | U16: =H16&"/"&IF(LEN(G16)=1,"0"&G16,G16)&"/2024" -> 28/02/2024 | V16: =IFERROR(VLOOKUP(K16,'List+TK'!$G$3:$H$16,2,0),"-") -> Phạm Minh Thuận | W16: =IF(N16="","",IF(I16="Nước ương tôm giống","Bể "&N16,"Ao "&N16)) -> Ao 6
A17: =_xlfn.AGGREGATE(3,3,$I$4:I17) -> 14 | B17: 14 | C17: Công ty TNHH CBTPXK Vạn Đức Tiền Giang | D17: Ấp Phú Bình | E17: Xã Vĩnh Bình | F17: Huyện Chợ Lách | G17: 2 | H17: 28 | I17: Cá tra nhỏ | J17: A1c | K17: Khanh | L17: =IFERROR(IF(F17="Huyện Mỏ Cày Nam","Mỏ Cày",RIGHT(F17,LEN(F17)-6)),"-") -> Chợ Lách | M17: =IFERROR(VLOOKUP(L17,'List+TK'!$I$3:$J$9,2,0),"-") -> 83/07 | N17: 23 | O17: =I17 -> Cá tra nhỏ | P17: ="83/"&IF(LEN(G17)=1,"0"&G17,G17)&"24/"&IF(LEN(B17)=1,"0"&B17,B17) -> 83/0224/14 | Q17: =L17&" "&M17 -> Chợ Lách 83/07 | R17: =C17&" - "&D17&", "&E17 -> Công ty TNHH CBTPXK Vạn Đức Tiền Giang - Ấp Phú Bình, Xã Vĩnh Bình | S17: =IF(OR(I17="Tôm chân trắng nhỏ",I17="Tôm sú nhỏ"),0.5,IF(OR(I17="Cá tra nhỏ",I17="Tôm sú thương phẩm",I17="Tôm chân trắng thương phẩm",I17="Tôm sú quảng canh",I17="Nước ương tôm giống"),1,IF(I17="Cá tra thương phẩm",1.5,0))) -> 1 | T17: =IFERROR(VLOOKUP(J17,'List+TK'!$D$3:$E$1000,2,0),"-") -> Methyltestosterone | U17: =H17&"/"&IF(LEN(G17)=1,"0"&G17,G17)&"/2024" -> 28/02/2024 | V17: =IFERROR(VLOOKUP(K17,'List+TK'!$G$3:$H$16,2,0),"-") -> Nguyễn Duy Khanh | W17: =IF(N17="","",IF(I17="Nước ương tôm giống","Bể "&N17,"Ao "&N17)) -> Ao 23
A18: =_xlfn.AGGREGATE(3,3,$I$4:I18) -> 15 | B18: 15 | C18: Công ty TNHH CBTPXK Vạn Đức Tiền Giang | D18: Ấp Phú Bình | E18: Xã Vĩnh Bình | F18: Huyện Chợ Lách | G18: 2 | H18: 28 | I18: Cá tra thương phẩm | J18: Nitroi | K18: Khanh | L18: =IFERROR(IF(F18="Huyện Mỏ Cày Nam","Mỏ Cày",RIGHT(F18,LEN(F18)-6)),"-") -> Chợ Lách | M18: =IFERROR(VLOOKUP(L18,'List+TK'!$I$3:$J$9,2,0),"-") -> 83/07 | N18: 8 | O18: =I18 -> Cá tra thương phẩm | P18: ="83/"&IF(LEN(G18)=1,"0"&G18,G18)&"24/"&IF(LEN(B18)=1,"0"&B18,B18) -> 83/0224/15 | Q18: =L18&" "&M18 -> Chợ Lách 83/07 | R18: =C18&" - "&D18&", "&E18 -> Công ty TNHH CBTPXK Vạn Đức Tiền Giang - Ấp Phú Bình, Xã Vĩnh Bình | S18: =IF(OR(I18="Tôm chân trắng nhỏ",I18="Tôm sú nhỏ"),0.5,IF(OR(I18="Cá tra nhỏ",I18="Tôm sú thương phẩm",I18="Tôm chân trắng thương phẩm",I18="Tôm sú quảng canh",I18="Nước ương tôm giống"),1,IF(I18="Cá tra thương phẩm",1.5,0))) -> 1.5 | T18: =IFERROR(VLOOKUP(J18,'List+TK'!$D$3:$E$1000,2,0),"-") -> Nhóm Nitroimidazoles | U18: =H18&"/"&IF(LEN(G18)=1,"0"&G18,G18)&"/2024" -> 28/02/2024 | V18: =IFERROR(VLOOKUP(K18,'List+TK'!$G$3:$H$16,2,0),"-") -> Nguyễn Duy Khanh | W18: =IF(N18="","",IF(I18="Nước ương tôm giống","Bể "&N18,"Ao "&N18)) -> Ao 8
... A26: =_xlfn.AGGREGATE(3,3,$I$4:I26) -> 23 | B26: 6 | C26: Công ty CP Gò Đàng | D26: Khu A Lộc Thuận, ấp Lộc Sơn | E26: Xã Lộc Thuận | F26: Huyện Bình Đại | G26: 3 | H26: 18 | I26: Cá tra thương phẩm | J26: Azadi | K26: Nguyên | L26: =IFERROR(IF(F26="Huyện Mỏ Cày Nam","Mỏ Cày",RIGHT(F26,LEN(F26)-6)),"-") -> Bình Đại | M26: =IFERROR(VLOOKUP(L26,'List+TK'!$I$3:$J$9,2,0),"-") -> 83/02 | N26: 3 | O26: =I26 -> Cá tra thương phẩm | P26: ="83/"&IF(LEN(G26)=1,"0"&G26,G26)&"24/"&IF(LEN(B26)=1,"0"&B26,B26) -> 83/0324/06 | Q26: =L26&" "&M26 -> Bình Đại 83/02 | R26: =C26&" - "&D26&", "&E26 -> Công ty CP Gò Đàng - Khu A Lộc Thuận, ấp Lộc Sơn, Xã Lộc Thuận | S26: =IF(OR(I26="Tôm chân trắng nhỏ",I26="Tôm sú nhỏ"),0.5,IF(OR(I26="Cá tra nhỏ",I26="Tôm sú thương phẩm",I26="Tôm chân trắng thương phẩm",I26="Tôm sú quảng canh",I26="Nước ương tôm giống"),1,IF(I26="Cá tra thương phẩm",1.5,0))) -> 1.5 | T26: =IFERROR(VLOOKUP(J26,'List+TK'!$D$3:$E$1000,2,0),"-") -> Azadirachtin | U26: =H26&"/"&IF(LEN(G26)=1,"0"&G26,G26)&"/2024" -> 18/03/2024 | V26: =IFERROR(VLOOKUP(K26,'List+TK'!$G$3:$H$16,2,0),"-") -> Cao Quang Nguyên | W26: =IF(N26="","",IF(I26="Nước ương tôm giống","Bể "&N26,"Ao "&N26)) -> Ao 3
A27: =_xlfn.AGGREGATE(3,3,$I$4:I27) -> 24 | B27: 7 | C27: Công ty TNHH Thực Phẩm Vạn Đức | D27: Ấp 7 | E27: Xã Thạnh Phước | F27: Huyện Bình Đại | G27: 3 | H27: 18 | I27: Cá chẽm nhỏ | J27: CAP | K27: Nguyên | L27: =IFERROR(IF(F27="Huyện Mỏ Cày Nam","Mỏ Cày",RIGHT(F27,LEN(F27)-6)),"-") -> Bình Đại | M27: =IFERROR(VLOOKUP(L27,'List+TK'!$I$3:$J$9,2,0),"-") -> 83/02 | N27: B10 | O27: =I27 -> Cá chẽm nhỏ | P27: ="83/"&IF(LEN(G27)=1,"0"&G27,G27)&"24/"&IF(LEN(B27)=1,"0"&B27,B27) -> 83/0324/07 | Q27: =L27&" "&M27 -> Bình Đại 83/02 | R27: =C27&" - "&D27&", "&E27 -> Công ty TNHH Thực Phẩm Vạn Đức - Ấp 7, Xã Thạnh Phước | S27: =IF(OR(I27="Tôm chân trắng nhỏ",I27="Tôm sú nhỏ"),0.5,IF(OR(I27="Cá tra nhỏ",I27="Tôm sú thương phẩm",I27="Tôm chân trắng thương phẩm",I27="Tôm sú quảng canh",I27="Nước ương tôm giống"),1,IF(I27="Cá tra thương phẩm",1.5,0))) -> 0 | T27: =IFERROR(VLOOKUP(J27,'List+TK'!$D$3:$E$1000,2,0),"-") -> Chloramphenicol | U27: =H27&"/"&IF(LEN(G27)=1,"0"&G27,G27)&"/2024" -> 18/03/2024 | V27: =IFERROR(VLOOKUP(K27,'List+TK'!$G$3:$H$16,2,0),"-") -> Cao Quang Nguyên | W27: =IF(N27="","",IF(I27="Nước ương tôm giống","Bể "&N27,"Ao "&N27)) -> Ao B10
A28: =_xlfn.AGGREGATE(3,3,$I$4:I28) -> 25 | B28: 8 | C28: Công ty TNHH Thực Phẩm Vạn Đức | D28: Ấp 7 | E28: Xã Thạnh Phước | F28: Huyện Bình Đại | G28: 3 | H28: 18 | I28: Cá chẽm thương phẩm | J28: NF | K28: Nguyên | L28: =IFERROR(IF(F28="Huyện Mỏ Cày Nam","Mỏ Cày",RIGHT(F28,LEN(F28)-6)),"-") -> Bình Đại | M28: =IFERROR(VLOOKUP(L28,'List+TK'!$I$3:$J$9,2,0),"-") -> 83/02 | N28: A20 | O28: =I28 -> Cá chẽm thương phẩm | P28: ="83/"&IF(LEN(G28)=1,"0"&G28,G28)&"24/"&IF(LEN(B28)=1,"0"&B28,B28) -> 83/0324/08 | Q28: =L28&" "&M28 -> Bình Đại 83/02 | R28: =C28&" - "&D28&", "&E28 -> Công ty TNHH Thực Phẩm Vạn Đức - Ấp 7, Xã Thạnh Phước | S28: =IF(OR(I28="Tôm chân trắng nhỏ",I28="Tôm sú nhỏ"),0.5,IF(OR(I28="Cá tra nhỏ",I28="Tôm sú thương phẩm",I28="Tôm chân trắng thương phẩm",I28="Tôm sú quảng canh",I28="Nước ương tôm giống"),1,IF(I28="Cá tra thương phẩm",1.5,0))) -> 0 | T28: =IFERROR(VLOOKUP(J28,'List+TK'!$D$3:$E$1000,2,0),"-") -> Nitrofurans | U28: =H28&"/"&IF(LEN(G28)=1,"0"&G28,G28)&"/2024" -> 18/03/2024 | V28: =IFERROR(VLOOKUP(K28,'List+TK'!$G$3:$H$16,2,0),"-") -> Cao Quang Nguyên | W28: =IF(N28="","",IF(I28="Nước ương tôm giống","Bể "&N28,"Ao "&N28)) -> Ao A20
A29: =_xlfn.AGGREGATE(3,3,$I$4:I29) -> 26 | B29: 9 | C29: Phạm Văn Cưng | E29: Xã An Thuận | F29: Huyện Thạnh Phú | G29: 3 | H29: 19 | I29: Tôm chân trắng thương phẩm | J29: NF | K29: Nguyên | L29: =IFERROR(IF(F29="Huyện Mỏ Cày Nam","Mỏ Cày",RIGHT(F29,LEN(F29)-6)),"-") -> Thạnh Phú | M29: =IFERROR(VLOOKUP(L29,'List+TK'!$I$3:$J$9,2,0),"-") -> 83/03 | N29: 1 | O29: =I29 -> Tôm chân trắng thương phẩm | P29: ="83/"&IF(LEN(G29)=1,"0"&G29,G29)&"24/"&IF(LEN(B29)=1,"0"&B29,B29) -> 83/0324/09 | Q29: =L29&" "&M29 -> Thạnh Phú 83/03 | R29: =C29&" - "&D29&", "&E29 -> Phạm Văn Cưng - , Xã An Thuận | S29: =IF(OR(I29="Tôm chân trắng nhỏ",I29="Tôm sú nhỏ"),0.5,IF(OR(I29="Cá tra nhỏ",I29="Tôm sú thương phẩm",I29="Tôm chân trắng thương phẩm",I29="Tôm sú quảng canh",I29="Nước ương tôm giống"),1,IF(I29="Cá tra thương phẩm",1.5,0))) -> 1 | T29: =IFERROR(VLOOKUP(J29,'List+TK'!$D$3:$E$1000,2,0),"-") -> Nitrofurans | U29: =H29&"/"&IF(LEN(G29)=1,"0"&G29,G29)&"/2024" -> 19/03/2024 | V29: =IFERROR(VLOOKUP(K29,'List+TK'!$G$3:$H$16,2,0),"-") -> Cao Quang Nguyên | W29: =IF(N29="","",IF(I29="Nước ương tôm giống","Bể "&N29,"Ao "&N29)) -> Ao 1
A30: =_xlfn.AGGREGATE(3,3,$I$4:I30) -> 27 | B30: 10 | C30: Công ty CP Gò Đàng | D30: Ấp Thành Long | E30: Xã Thành Thới A | F30: Huyện Mỏ Cày Nam | G30: 3 | H30: 19 | I30: Cá tra nhỏ | J30: CAP | K30: Thuận | L30: =IFERROR(IF(F30="Huyện Mỏ Cày Nam","Mỏ Cày",RIGHT(F30,LEN(F30)-6)),"-") -> Mỏ Cày | M30: =IFERROR(VLOOKUP(L30,'List+TK'!$I$3:$J$9,2,0),"-") -> 83/04 | N30: 1 | O30: =I30 -> Cá tra nhỏ | P30: ="83/"&IF(LEN(G30)=1,"0"&G30,G30)&"24/"&IF(LEN(B30)=1,"0"&B30,B30) -> 83/0324/10 | Q30: =L30&" "&M30 -> Mỏ Cày 83/04 | R30: =C30&" - "&D30&", "&E30 -> Công ty CP Gò Đàng - Ấp Thành Long, Xã Thành Thới A | S30: =IF(OR(I30="Tôm chân trắng nhỏ",I30="Tôm sú nhỏ"),0.5,IF(OR(I30="Cá tra nhỏ",I30="Tôm sú thương phẩm",I30="Tôm chân trắng thương phẩm",I30="Tôm sú quảng canh",I30="Nước ương tôm giống"),1,IF(I30="Cá tra thương phẩm",1.5,0))) -> 1 | T30: =IFERROR(VLOOKUP(J30,'List+TK'!$D$3:$E$1000,2,0),"-") -> Chloramphenicol | U30: =H30&"/"&IF(LEN(G30)=1,"0"&G30,G30)&"/2024" -> 19/03/2024 | V30: =IFERROR(VLOOKUP(K30,'List+TK'!$G$3:$H$16,2,0),"-") -> Phạm Minh Thuận | W30: =IF(N30="","",IF(I30="Nước ương tôm giống","Bể "&N30,"Ao "&N30)) -> Ao 1
A31: =_xlfn.AGGREGATE(3,3,$I$4:I31) -> 28 | B31: 11 | C31: Công ty CP Gò Đàng | D31: Ấp Thành Long | E31: Xã Thành Thới A | F31: Huyện Mỏ Cày Nam | G31: 3 | H31: 19 | I31: Cá tra nhỏ | J31: NF | K31: Thuận | L31: =IFERROR(IF(F31="Huyện Mỏ Cày Nam","Mỏ Cày",RIGHT(F31,LEN(F31)-6)),"-") -> Mỏ Cày | M31: =IFERROR(VLOOKUP(L31,'List+TK'!$I$3:$J$9,2,0),"-") -> 83/04 | N31: 3 | O31: =I31 -> Cá tra nhỏ | P31: ="83/"&IF(LEN(G31)=1,"0"&G31,G31)&"24/"&IF(LEN(B31)=1,"0"&B31,B31) -> 83/0324/11 | Q31: =L31&" "&M31 -> Mỏ Cày 83/04 | R31: =C31&" - "&D31&", "&E31 -> Công ty CP Gò Đàng - Ấp Thành Long, Xã Thành Thới A | S31: =IF(OR(I31="Tôm chân trắng nhỏ",I31="Tôm sú nhỏ"),0.5,IF(OR(I31="Cá tra nhỏ",I31="Tôm sú thương phẩm",I31="Tôm chân trắng thương phẩm",I31="Tôm sú quảng canh",I31="Nước ương tôm giống"),1,IF(I31="Cá tra thương phẩm",1.5,0))) -> 1 | T31: =IFERROR(VLOOKUP(J31,'List+TK'!$D$3:$E$1000,2,0),"-") -> Nitrofurans | U31: =H31&"/"&IF(LEN(G31)=1,"0"&G31,G31)&"/2024" -> 19/03/2024 | V31: =IFERROR(VLOOKUP(K31,'List+TK'!$G$3:$H$16,2,0),"-") -> Phạm Minh Thuận | W31: =IF(N31="","",IF(I31="Nước ương tôm giống","Bể "&N31,"Ao "&N31)) -> Ao 3
A32: =_xlfn.AGGREGATE(3,3,$I$4:I32) -> 29 | B32: 12 | C32: Trại nuôi cá tra Thành Hưng | D32: Ấp Phú Tân | E32: Xã Phú Túc | F32: Huyện Châu Thành | G32: 3 | H32: 18 | I32: Cá tra thương phẩm | J32: CAP | K32: Khanh | L32: =IFERROR(IF(F32="Huyện Mỏ Cày Nam","Mỏ Cày",RIGHT(F32,LEN(F32)-6)),"-") -> Châu Thành | M32: =IFERROR(VLOOKUP(L32,'List+TK'!$I$3:$J$9,2,0),"-") -> 83/05 | N32: 1 | O32: =I32 -> Cá tra thương phẩm | P32: ="83/"&IF(LEN(G32)=1,"0"&G32,G32)&"24/"&IF(LEN(B32)=1,"0"&B32,B32) -> 83/0324/12 | Q32: =L32&" "&M32 -> Châu Thành 83/05 | R32: =C32&" - "&D32&", "&E32 -> Trại nuôi cá tra Thành Hưng - Ấp Phú Tân, Xã Phú Túc | S32: =IF(OR(I32="Tôm chân trắng nhỏ",I32="Tôm sú nhỏ"),0.5,IF(OR(I32="Cá tra nhỏ",I32="Tôm sú thương phẩm",I32="Tôm chân trắng thương phẩm",I32="Tôm sú quảng canh",I32="Nước ương tôm giống"),1,IF(I32="Cá tra thương phẩm",1.5,0))) -> 1.5 | T32: =IFERROR(VLOOKUP(J32,'List+TK'!$D$3:$E$1000,2,0),"-") -> Chloramphenicol | U32: =H32&"/"&IF(LEN(G32)=1,"0"&G32,G32)&"/2024" -> 18/03/2024 | V32: =IFERROR(VLOOKUP(K32,'List+TK'!$G$3:$H$16,2,0),"-") -> Nguyễn Duy Khanh | W32: =IF(N32="","",IF(I32="Nước ương tôm giống","Bể "&N32,"Ao "&N32)) -> Ao 1
A33: =_xlfn.AGGREGATE(3,3,$I$4:I33) -> 30 | B33: 13 | C33: Trại nuôi cá tra Thành Hưng | D33: Ấp Phú Tân | E33: Xã Phú Túc | F33: Huyện Châu Thành | G33: 3 | H33: 18 | I33: Cá tra thương phẩm | J33: NF | K33: Khanh | L33: =IFERROR(IF(F33="Huyện Mỏ Cày Nam","Mỏ Cày",RIGHT(F33,LEN(F33)-6)),"-") -> Châu Thành | M33: =IFERROR(VLOOKUP(L33,'List+TK'!$I$3:$J$9,2,0),"-") -> 83/05 | N33: 6 | O33: =I33 -> Cá tra thương phẩm | P33: ="83/"&IF(LEN(G33)=1,"0"&G33,G33)&"24/"&IF(LEN(B33)=1,"0"&B33,B33) -> 83/0324/13 | Q33: =L33&" "&M33 -> Châu Thành 83/05 | R33: =C33&" - "&D33&", "&E33 -> Trại nuôi cá tra Thành Hưng - Ấp Phú Tân, Xã Phú Túc | S33: =IF(OR(I33="Tôm chân trắng nhỏ",I33="Tôm sú nhỏ"),0.5,IF(OR(I33="Cá tra nhỏ",I33="Tôm sú thương phẩm",I33="Tôm chân trắng thương phẩm",I33="Tôm sú quảng canh",I33="Nước ương tôm giống"),1,IF(I33="Cá tra thương phẩm",1.5,0))) -> 1.5 | T33: =IFERROR(VLOOKUP(J33,'List+TK'!$D$3:$E$1000,2,0),"-") -> Nitrofurans | U33: =H33&"/"&IF(LEN(G33)=1,"0"&G33,G33)&"/2024" -> 18/03/2024 | V33: =IFERROR(VLOOKUP(K33,'List+TK'!$G$3:$H$16,2,0),"-") -> Nguyễn Duy Khanh | W33: =IF(N33="","",IF(I33="Nước ương tôm giống","Bể "&N33,"Ao "&N33)) -> Ao 6
A34: =_xlfn.AGGREGATE(3,3,$I$4:I34) -> 31 | B34: 14 | C34: Trại nuôi cá tra Thành Hưng | D34: Ấp Phú Tân | E34: Xã Phú Túc | F34: Huyện Châu Thành | G34: 3 | H34: 18 | I34: Cá tra thương phẩm | J34: Orme | K34: Khanh | L34: =IFERROR(IF(F34="Huyện Mỏ Cày Nam","Mỏ Cày",RIGHT(F34,LEN(F34)-6)),"-") -> Châu Thành | M34: =IFERROR(VLOOKUP(L34,'List+TK'!$I$3:$J$9,2,0),"-") -> 83/05 | N34: 8 | O34: =I34 -> Cá tra thương phẩm | P34: ="83/"&IF(LEN(G34)=1,"0"&G34,G34)&"24/"&IF(LEN(B34)=1,"0"&B34,B34) -> 83/0324/14 | Q34: =L34&" "&M34 -> Châu Thành 83/05 | R34: =C34&" - "&D34&", "&E34 -> Trại nuôi cá tra Thành Hưng - Ấp Phú Tân, Xã Phú Túc | S34: =IF(OR(I34="Tôm chân trắng nhỏ",I34="Tôm sú nhỏ"),0.5,IF(OR(I34="Cá tra nhỏ",I34="Tôm sú thương phẩm",I34="Tôm chân trắng thương phẩm",I34="Tôm sú quảng canh",I34="Nước ương tôm giống"),1,IF(I34="Cá tra thương phẩm",1.5,0))) -> 1.5 | T34: =IFERROR(VLOOKUP(J34,'List+TK'!$D$3:$E$1000,2,0),"-") -> Ormetoprim | U34: =H34&"/"&IF(LEN(G34)=1,"0"&G34,G34)&"/2024" -> 18/03/2024 | V34: =IFERROR(VLOOKUP(K34,'List+TK'!$G$3:$H$16,2,0),"-") -> Nguyễn Duy Khanh | W34: =IF(N34="","",IF(I34="Nước ương tôm giống","Bể "&N34,"Ao "&N34)) -> Ao 8
A35: =_xlfn.AGGREGATE(3,3,$I$4:I35) -> 32 | B35: 15 | C35: Công ty CP Gò Đàng | D35: Ấp 1 | E35: Xã Hưng Phong | F35: Huyện Giồng Trôm | G35: 3 | H35: 20 | I35: Cá tra thương phẩm | J35: Nitroi | K35: Thuận | L35: =IFERROR(IF(F35="Huyện Mỏ Cày Nam","Mỏ Cày",RIGHT(F35,LEN(F35)-6)),"-") -> Giồng Trôm | M35: =IFERROR(VLOOKUP(L35,'List+TK'!$I$3:$J$9,2,0),"-") -> 83/06 | N35: 5 | O35: =I35 -> Cá tra thương phẩm | P35: ="83/"&IF(LEN(G35)=1,"0"&G35,G35)&"24/"&IF(LEN(B35)=1,"0"&B35,B35) -> 83/0324/15 | Q35: =L35&" "&M35 -> Giồng Trôm 83/06 | R35: =C35&" - "&D35&", "&E35 -> Công ty CP Gò Đàng - Ấp 1, Xã Hưng Phong | S35: =IF(OR(I35="Tôm chân trắng nhỏ",I35="Tôm sú nhỏ"),0.5,IF(OR(I35="Cá tra nhỏ",I35="Tôm sú thương phẩm",I35="Tôm chân trắng thương phẩm",I35="Tôm sú quảng canh",I35="Nước ương tôm giống"),1,IF(I35="Cá tra thương phẩm",1.5,0))) -> 1.5 | T35: =IFERROR(VLOOKUP(J35,'List+TK'!$D$3:$E$1000,2,0),"-") -> Nhóm Nitroimidazoles | U35: =H35&"/"&IF(LEN(G35)=1,"0"&G35,G35)&"/2024" -> 20/03/2024 | V35: =IFERROR(VLOOKUP(K35,'List+TK'!$G$3:$H$16,2,0),"-") -> Phạm Minh Thuận | W35: =IF(N35="","",IF(I35="Nước ương tôm giống","Bể "&N35,"Ao "&N35)) -> Ao 5
A36: =_xlfn.AGGREGATE(3,3,$I$4:I36) -> 33 | B36: 16 | C36: Công ty CP Gò Đàng | D36: Ấp 1 | E36: Xã Hưng Phong | F36: Huyện Giồng Trôm | G36: 3 | H36: 20 | I36: Cá tra thương phẩm | J36: KLN | K36: Thuận | L36: =IFERROR(IF(F36="Huyện Mỏ Cày Nam","Mỏ Cày",RIGHT(F36,LEN(F36)-6)),"-") -> Giồng Trôm | M36: =IFERROR(VLOOKUP(L36,'List+TK'!$I$3:$J$9,2,0),"-") -> 83/06 | N36: 3 | O36: =I36 -> Cá tra thương phẩm | P36: ="83/"&IF(LEN(G36)=1,"0"&G36,G36)&"24/"&IF(LEN(B36)=1,"0"&B36,B36) -> 83/0324/16 | Q36: =L36&" "&M36 -> Giồng Trôm 83/06 | R36: =C36&" - "&D36&", "&E36 -> Công ty CP Gò Đàng - Ấp 1, Xã Hưng Phong | S36: =IF(OR(I36="Tôm chân trắng nhỏ",I36="Tôm sú nhỏ"),0.5,IF(OR(I36="Cá tra nhỏ",I36="Tôm sú thương phẩm",I36="Tôm chân trắng thương phẩm",I36="Tôm sú quảng canh",I36="Nước ương tôm giống"),1,IF(I36="Cá tra thương phẩm",1.5,0))) -> 1.5 | T36: =IFERROR(VLOOKUP(J36,'List+TK'!$D$3:$E$1000,2,0),"-") -> Pb, Hg, Cd | U36: =H36&"/"&IF(LEN(G36)=1,"0"&G36,G36)&"/2024" -> 20/03/2024 | V36: =IFERROR(VLOOKUP(K36,'List+TK'!$G$3:$H$16,2,0),"-") -> Phạm Minh Thuận | W36: =IF(N36="","",IF(I36="Nước ương tôm giống","Bể "&N36,"Ao "&N36)) -> Ao 3
A37: =_xlfn.AGGREGATE(3,3,$I$4:I37) -> 34 | B37: 17 | C37: Công ty CP Gò Đàng | D37: Ấp 1 | E37: Xã Hưng Phong | F37: Huyện Giồng Trôm | G37: 3 | H37: 20 | I37: Cá tra thương phẩm | J37: Thuốc BVTV | K37: Thuận | L37: =IFERROR(IF(F37="Huyện Mỏ Cày Nam","Mỏ Cày",RIGHT(F37,LEN(F37)-6)),"-") -> Giồng Trôm | M37: =IFERROR(VLOOKUP(L37,'List+TK'!$I$3:$J$9,2,0),"-") -> 83/06 | N37: 2 | O37: =I37 -> Cá tra thương phẩm | P37: ="83/"&IF(LEN(G37)=1,"0"&G37,G37)&"24/"&IF(LEN(B37)=1,"0"&B37,B37) -> 83/0324/17 | Q37: =L37&" "&M37 -> Giồng Trôm 83/06 | R37: =C37&" - "&D37&", "&E37 -> Công ty CP Gò Đàng - Ấp 1, Xã Hưng Phong | S37: =IF(OR(I37="Tôm chân trắng nhỏ",I37="Tôm sú nhỏ"),0.5,IF(OR(I37="Cá tra nhỏ",I37="Tôm sú thương phẩm",I37="Tôm chân trắng thương phẩm",I37="Tôm sú quảng canh",I37="Nước ương tôm giống"),1,IF(I37="Cá tra thương phẩm",1.5,0))) -> 1.5 | T37: =IFERROR(VLOOKUP(J37,'List+TK'!$D$3:$E$1000,2,0),"-") -> Thuốc trừ sâu gốc Chlor hữu cơ; phospho hữu cơ; cúc tổng hợp… | U37: =H37&"/"&IF(LEN(G37)=1,"0"&G37,G37)&"/2024" -> 20/03/2024 | V37: =IFERROR(VLOOKUP(K37,'List+TK'!$G$3:$H$16,2,0),"-") -> Phạm Minh Thuận | W37: =IF(N37="","",IF(I37="Nước ương tôm giống","Bể "&N37,"Ao "&N37)) -> Ao 2
A38: =_xlfn.AGGREGATE(3,3,$I$4:I38) -> 35 | B38: 18 | C38: Công ty CP Thủy sản Vinh Quang | D38: Ấp Quân Bình | E38: Xã Tân Thiềng | F38: Huyện Chợ Lách | G38: 3 | H38: 19 | I38: Cá tra thương phẩm | J38: MG+LMG | K38: Khanh | L38: =IFERROR(IF(F38="Huyện Mỏ Cày Nam","Mỏ Cày",RIGHT(F38,LEN(F38)-6)),"-") -> Chợ Lách | M38: =IFERROR(VLOOKUP(L38,'List+TK'!$I$3:$J$9,2,0),"-") -> 83/07 | N38: 1B | O38: =I38 -> Cá tra thương phẩm | P38: ="83/"&IF(LEN(G38)=1,"0"&G38,G38)&"24/"&IF(LEN(B38)=1,"0"&B38,B38) -> 83/0324/18 | Q38: =L38&" "&M38 -> Chợ Lách 83/07 | R38: =C38&" - "&D38&", "&E38 -> Công ty CP Thủy sản Vinh Quang - Ấp Quân Bình, Xã Tân Thiềng | S38: =IF(OR(I38="Tôm chân trắng nhỏ",I38="Tôm sú nhỏ"),0.5,IF(OR(I38="Cá tra nhỏ",I38="Tôm sú thương phẩm",I38="Tôm chân trắng thương phẩm",I38="Tôm sú quảng canh",I38="Nước ương tôm giống"),1,IF(I38="Cá tra thương phẩm",1.5,0))) -> 1.5 | T38: =IFERROR(VLOOKUP(J38,'List+TK'!$D$3:$E$1000,2,0),"-") -> Malachite Green, Leuco Malachite Green | U38: =H38&"/"&IF(LEN(G38)=1,"0"&G38,G38)&"/2024" -> 19/03/2024 | V38: =IFERROR(VLOOKUP(K38,'List+TK'!$G$3:$H$16,2,0),"-") -> Nguyễn Duy Khanh | W38: =IF(N38="","",IF(I38="Nước ương tôm giống","Bể "&N38,"Ao "&N38)) -> Ao 1B
A39: =_xlfn.AGGREGATE(3,3,$I$4:I39) -> 36 | B39: 19 | C39: Công ty CP Thủy sản Vinh Quang | D39: Ấp Quân Bình | E39: Xã Tân Thiềng | F39: Huyện Chợ Lách | G39: 3 | H39: 19 | I39: Cá tra thương phẩm | J39: Iver | K39: Khanh | L39: =IFERROR(IF(F39="Huyện Mỏ Cày Nam","Mỏ Cày",RIGHT(F39,LEN(F39)-6)),"-") -> Chợ Lách | M39: =IFERROR(VLOOKUP(L39,'List+TK'!$I$3:$J$9,2,0),"-") -> 83/07 | N39: 3B | O39: =I39 -> Cá tra thương phẩm | P39: ="83/"&IF(LEN(G39)=1,"0"&G39,G39)&"24/"&IF(LEN(B39)=1,"0"&B39,B39) -> 83/0324/19 | Q39: =L39&" "&M39 -> Chợ Lách 83/07 | R39: =C39&" - "&D39&", "&E39 -> Công ty CP Thủy sản Vinh Quang - Ấp Quân Bình, Xã Tân Thiềng | S39: =IF(OR(I39="Tôm chân trắng nhỏ",I39="Tôm sú nhỏ"),0.5,IF(OR(I39="Cá tra nhỏ",I39="Tôm sú thương phẩm",I39="Tôm chân trắng thương phẩm",I39="Tôm sú quảng canh",I39="Nước ương tôm giống"),1,IF(I39="Cá tra thương phẩm",1.5,0))) -> 1.5 | T39: =IFERROR(VLOOKUP(J39,'List+TK'!$D$3:$E$1000,2,0),"-") -> Ivermectin | U39: =H39&"/"&IF(LEN(G39)=1,"0"&G39,G39)&"/2024" -> 19/03/2024 | V39: =IFERROR(VLOOKUP(K39,'List+TK'!$G$3:$H$16,2,0),"-") -> Nguyễn Duy Khanh | W39: =IF(N39="","",IF(I39="Nước ương tôm giống","Bể "&N39,"Ao "&N39)) -> Ao 3B
A40: =_xlfn.AGGREGATE(3,3,$I$4:I40) -> 37 | B40: 20 | C40: Công ty CP Thủy sản Vinh Quang | D40: Ấp Quân Bình | E40: Xã Tân Thiềng | F40: Huyện Chợ Lách | G40: 3 | H40: 19 | I40: Cá tra thương phẩm | J40: Aver | K40: Khanh | L40: =IFERROR(IF(F40="Huyện Mỏ Cày Nam","Mỏ Cày",RIGHT(F40,LEN(F40)-6)),"-") -> Chợ Lách | M40: =IFERROR(VLOOKUP(L40,'List+TK'!$I$3:$J$9,2,0),"-") -> 83/07 | N40: 1 | O40: =I40 -> Cá tra thương phẩm | P40: ="83/"&IF(LEN(G40)=1,"0"&G40,G40)&"24/"&IF(LEN(B40)=1,"0"&B40,B40) -> 83/0324/20 | Q40: =L40&" "&M40 -> Chợ Lách 83/07 | R40: =C40&" - "&D40&", "&E40 -> Công ty CP Thủy sản Vinh Quang - Ấp Quân Bình, Xã Tân Thiềng | S40: =IF(OR(I40="Tôm chân trắng nhỏ",I40="Tôm sú nhỏ"),0.5,IF(OR(I40="Cá tra nhỏ",I40="Tôm sú thương phẩm",I40="Tôm chân trắng thương phẩm",I40="Tôm sú quảng canh",I40="Nước ương tôm giống"),1,IF(I40="Cá tra thương phẩm",1.5,0))) -> 1.5 | T40: =IFERROR(VLOOKUP(J40,'List+TK'!$D$3:$E$1000,2,0),"-") -> Avermectin B1a (Abarmectin B1a) | U40: =H40&"/"&IF(LEN(G40)=1,"0"&G40,G40)&"/2024" -> 19/03/2024 | V40: =IFERROR(VLOOKUP(K40,'List+TK'!$G$3:$H$16,2,0),"-") -> Nguyễn Duy Khanh | W40: =IF(N40="","",IF(I40="Nước ương tôm giống","Bể "&N40,"Ao "&N40)) -> Ao 1
A41: =_xlfn.AGGREGATE(3,3,$I$4:I41) -> 38 | B41: 21 | C41: Công ty CP Thủy sản Vinh Quang | D41: Ấp Quân Bình | E41: Xã Tân Thiềng | F41: Huyện Chợ Lách | G41: 3 | H41: 19 | I41: Cá tra thương phẩm | J41: Praz | K41: Khanh | L41: =IFERROR(IF(F41="Huyện Mỏ Cày Nam","Mỏ Cày",RIGHT(F41,LEN(F41)-6)),"-") -> Chợ Lách | M41: =IFERROR(VLOOKUP(L41,'List+TK'!$I$3:$J$9,2,0),"-") -> 83/07 | N41: 3 | O41: =I41 -> Cá tra thương phẩm | P41: ="83/"&IF(LEN(G41)=1,"0"&G41,G41)&"24/"&IF(LEN(B41)=1,"0"&B41,B41) -> 83/0324/21 | Q41: =L41&" "&M41 -> Chợ Lách 83/07 | R41: =C41&" - "&D41&", "&E41 -> Công ty CP Thủy sản Vinh Quang - Ấp Quân Bình, Xã Tân Thiềng | S41: =IF(OR(I41="Tôm chân trắng nhỏ",I41="Tôm sú nhỏ"),0.5,IF(OR(I41="Cá tra nhỏ",I41="Tôm sú thương phẩm",I41="Tôm chân trắng thương phẩm",I41="Tôm sú quảng canh",I41="Nước ương tôm giống"),1,IF(I41="Cá tra thương phẩm",1.5,0))) -> 1.5 | T41: =IFERROR(VLOOKUP(J41,'List+TK'!$D$3:$E$1000,2,0),"-") -> Praziquantel | U41: =H41&"/"&IF(LEN(G41)=1,"0"&G41,G41)&"/2024" -> 19/03/2024 | V41: =IFERROR(VLOOKUP(K41,'List+TK'!$G$3:$H$16,2,0),"-") -> Nguyễn Duy Khanh | W41: =IF(N41="","",IF(I41="Nước ương tôm giống","Bể "&N41,"Ao "&N41)) -> Ao 3
A42: =_xlfn.AGGREGATE(3,3,$I$4:I42) -> 39 | B42: 22 | C42: Công ty CP Thủy sản Vinh Quang | D42: Ấp Quân Bình | E42: Xã Sơn Định | F42: Huyện Chợ Lách | G42: 3 | H42: 19 | I42: Cá tra thương phẩm | J42: Trich | K42: Khanh | L42: =IFERROR(IF(F42="Huyện Mỏ Cày Nam","Mỏ Cày",RIGHT(F42,LEN(F42)-6)),"-") -> Chợ Lách | M42: =IFERROR(VLOOKUP(L42,'List+TK'!$I$3:$J$9,2,0),"-") -> 83/07 | N42: 4 | O42: =I42 -> Cá tra thương phẩm | P42: ="83/"&IF(LEN(G42)=1,"0"&G42,G42)&"24/"&IF(LEN(B42)=1,"0"&B42,B42) -> 83/0324/22 | Q42: =L42&" "&M42 -> Chợ Lách 83/07 | R42: =C42&" - "&D42&", "&E42 -> Công ty CP Thủy sản Vinh Quang - Ấp Quân Bình, Xã Sơn Định | S42: =IF(OR(I42="Tôm chân trắng nhỏ",I42="Tôm sú nhỏ"),0.5,IF(OR(I42="Cá tra nhỏ",I42="Tôm sú thương phẩm",I42="Tôm chân trắng thương phẩm",I42="Tôm sú quảng canh",I42="Nước ương tôm giống"),1,IF(I42="Cá tra thương phẩm",1.5,0))) -> 1.5 | T42: =IFERROR(VLOOKUP(J42,'List+TK'!$D$3:$E$1000,2,0),"-") -> Trichlorfon (Dipterex) | U42: =H42&"/"&IF(LEN(G42)=1,"0"&G42,G42)&"/2024" -> 19/03/2024 | V42: =IFERROR(VLOOKUP(K42,'List+TK'!$G$3:$H$16,2,0),"-") -> Nguyễn Duy Khanh | W42: =IF(N42="","",IF(I42="Nước ương tôm giống","Bể "&N42,"Ao "&N42)) -> Ao 4
A43: =_xlfn.AGGREGATE(3,3,$I$4:I43) -> 40 | B43: 1 | C43: Nguyễn Văn Út | D43: Ấp 7 | E43: Thị Trấn Tiệm Tôm | F43: Huyện Ba Tri | G43: 4 | H43: 09 | I43: Tôm sú thương phẩm | J43: NF | K43: Thuận | L43: =IFERROR(IF(F43="Huyện Mỏ Cày Nam","Mỏ Cày",RIGHT(F43,LEN(F43)-6)),"-") -> Ba Tri | M43: =IFERROR(VLOOKUP(L43,'List+TK'!$I$3:$J$9,2,0),"-") -> 83/01 | N43: 1 | O43: =I43 -> Tôm sú thương phẩm | P43: ="83/"&IF(LEN(G43)=1,"0"&G43,G43)&"24/"&IF(LEN(B43)=1,"0"&B43,B43) -> 83/0424/01 | Q43: =L43&" "&M43 -> Ba Tri 83/01 | R43: =C43&" - "&D43&", "&E43 -> Nguyễn Văn Út - Ấp 7, Thị Trấn Tiệm Tôm | S43: =IF(OR(I43="Tôm chân trắng nhỏ",I43="Tôm sú nhỏ"),0.5,IF(OR(I43="Cá tra nhỏ",I43="Tôm sú thương phẩm",I43="Tôm chân trắng thương phẩm",I43="Tôm sú quảng canh",I43="Nước ương tôm giống"),1,IF(I43="Cá tra thương phẩm",1.5,0))) -> 1 | T43: =IFERROR(VLOOKUP(J43,'List+TK'!$D$3:$E$1000,2,0),"-") -> Nitrofurans | U43: =H43&"/"&IF(LEN(G43)=1,"0"&G43,G43)&"/2024" -> 09/04/2024 | V43: =IFERROR(VLOOKUP(K43,'List+TK'!$G$3:$H$16,2,0),"-") -> Phạm Minh Thuận | W43: =IF(N43="","",IF(I43="Nước ương tôm giống","Bể "&N43,"Ao "&N43)) -> Ao 1
A44: =_xlfn.AGGREGATE(3,3,$I$4:I44) -> 41 | B44: 2 | C44: Phạm Văn Tư | D44: Ấp 8 | E44: Thị Trấn Tiệm Tôm | F44: Huyện Ba Tri | G44: 4 | H44: 09 | I44: Tôm chân trắng nhỏ | J44: NF | K44: Thuận | L44: =IFERROR(IF(F44="Huyện Mỏ Cày Nam","Mỏ Cày",RIGHT(F44,LEN(F44)-6)),"-") -> Ba Tri | M44: =IFERROR(VLOOKUP(L44,'List+TK'!$I$3:$J$9,2,0),"-") -> 83/01 | N44: 2 | O44: =I44 -> Tôm chân trắng nhỏ | P44: ="83/"&IF(LEN(G44)=1,"0"&G44,G44)&"24/"&IF(LEN(B44)=1,"0"&B44,B44) -> 83/0424/02 | Q44: =L44&" "&M44 -> Ba Tri 83/01 | R44: =C44&" - "&D44&", "&E44 -> Phạm Văn Tư - Ấp 8, Thị Trấn Tiệm Tôm | S44: =IF(OR(I44="Tôm chân trắng nhỏ",I44="Tôm sú nhỏ"),0.5,IF(OR(I44="Cá tra nhỏ",I44="Tôm sú thương phẩm",I44="Tôm chân trắng thương phẩm",I44="Tôm sú quảng canh",I44="Nước ương tôm giống"),1,IF(I44="Cá tra thương phẩm",1.5,0))) -> 0.5 | T44: =IFERROR(VLOOKUP(J44,'List+TK'!$D$3:$E$1000,2,0),"-") -> Nitrofurans | U44: =H44&"/"&IF(LEN(G44)=1,"0"&G44,G44)&"/2024" -> 09/04/2024 | V44: =IFERROR(VLOOKUP(K44,'List+TK'!$G$3:$H$16,2,0),"-") -> Phạm Minh Thuận | W44: =IF(N44="","",IF(I44="Nước ương tôm giống","Bể "&N44,"Ao "&N44)) -> Ao 2
A45: =_xlfn.AGGREGATE(3,3,$I$4:I45) -> 42 | B45: 3 | C45: Công ty TNHH Thực Phẩm Vạn Đức | D45: Ấp 6 | E45: Xã Bảo Thạnh | F45: Huyện Ba Tri | G45: 4 | H45: 09 | I45: Cá chẽm thương phẩm | J45: CV+LCV | K45: Thuận | L45: =IFERROR(IF(F45="Huyện Mỏ Cày Nam","Mỏ Cày",RIGHT(F45,LEN(F45)-6)),"-") -> Ba Tri | M45: =IFERROR(VLOOKUP(L45,'List+TK'!$I$3:$J$9,2,0),"-") -> 83/01 | N45: A10 | O45: =I45 -> Cá chẽm thương phẩm | P45: ="83/"&IF(LEN(G45)=1,"0"&G45,G45)&"24/"&IF(LEN(B45)=1,"0"&B45,B45) -> 83/0424/03 | Q45: =L45&" "&M45 -> Ba Tri 83/01 | R45: =C45&" - "&D45&", "&E45 -> Công ty TNHH Thực Phẩm Vạn Đức - Ấp 6, Xã Bảo Thạnh | S45: =IF(OR(I45="Tôm chân trắng nhỏ",I45="Tôm sú nhỏ"),0.5,IF(OR(I45="Cá tra nhỏ",I45="Tôm sú thương phẩm",I45="Tôm chân trắng thương phẩm",I45="Tôm sú quảng canh",I45="Nước ương tôm giống"),1,IF(I45="Cá tra thương phẩm",1.5,0))) -> 0 | T45: =IFERROR(VLOOKUP(J45,'List+TK'!$D$3:$E$1000,2,0),"-") -> Crystal Violet, Leuco Crystal Violet | U45: =H45&"/"&IF(LEN(G45)=1,"0"&G45,G45)&"/2024" -> 09/04/2024 | V45: =IFERROR(VLOOKUP(K45,'List+TK'!$G$3:$H$16,2,0),"-") -> Phạm Minh Thuận | W45: =IF(N45="","",IF(I45="Nước ương tôm giống","Bể "&N45,"Ao "&N45)) -> Ao A10
A46: =_xlfn.AGGREGATE(3,3,$I$4:I46) -> 43 | B46: 4 | C46: Nguyễn Văn Mười | D46: Ấp Bình Thạnh 3 | E46: Xã Thạnh Trị | F46: Huyện Bình Đại | G46: 4 | H46: 09 | I46: Tôm sú thương phẩm | J46: MG+LMG | K46: Nguyên | L46: =IFERROR(IF(F46="Huyện Mỏ Cày Nam","Mỏ Cày",RIGHT(F46,LEN(F46)-6)),"-") -> Bình Đại | M46: =IFERROR(VLOOKUP(L46,'List+TK'!$I$3:$J$9,2,0),"-") -> 83/02 | N46: 1 | O46: =I46 -> Tôm sú thương phẩm | P46: ="83/"&IF(LEN(G46)=1,"0"&G46,G46)&"24/"&IF(LEN(B46)=1,"0"&B46,B46) -> 83/0424/04 | Q46: =L46&" "&M46 -> Bình Đại 83/02 | R46: =C46&" - "&D46&", "&E46 -> Nguyễn Văn Mười - Ấp Bình Thạnh 3, Xã Thạnh Trị | S46: =IF(OR(I46="Tôm chân trắng nhỏ",I46="Tôm sú nhỏ"),0.5,IF(OR(I46="Cá tra nhỏ",I46="Tôm sú thương phẩm",I46="Tôm chân trắng thương phẩm",I46="Tôm sú quảng canh",I46="Nước ương tôm giống"),1,IF(I46="Cá tra thương phẩm",1.5,0))) -> 1 | T46: =IFERROR(VLOOKUP(J46,'List+TK'!$D$3:$E$1000,2,0),"-") -> Malachite Green, Leuco Malachite Green | U46: =H46&"/"&IF(LEN(G46)=1,"0"&G46,G46)&"/2024" -> 09/04/2024 | V46: =IFERROR(VLOOKUP(K46,'List+TK'!$G$3:$H$16,2,0),"-") -> Cao Quang Nguyên | W46: =IF(N46="","",IF(I46="Nước ương tôm giống","Bể "&N46,"Ao "&N46)) -> Ao 1
A47: =_xlfn.AGGREGATE(3,3,$I$4:I47) -> 44 | B47: 5 | C47: Nguyễn Văn Mười | D47: Ấp Bình Thạnh 3 | E47: Xã Thạnh Trị | F47: Huyện Bình Đại | G47: 4 | H47: 09 | I47: Tôm chân trắng thương phẩm | J47: Orme | K47: Nguyên | L47: =IFERROR(IF(F47="Huyện Mỏ Cày Nam","Mỏ Cày",RIGHT(F47,LEN(F47)-6)),"-") -> Bình Đại | M47: =IFERROR(VLOOKUP(L47,'List+TK'!$I$3:$J$9,2,0),"-") -> 83/02 | N47: 2 | O47: =I47 -> Tôm chân trắng thương phẩm | P47: ="83/"&IF(LEN(G47)=1,"0"&G47,G47)&"24/"&IF(LEN(B47)=1,"0"&B47,B47) -> 83/0424/05 | Q47: =L47&" "&M47 -> Bình Đại 83/02 | R47: =C47&" - "&D47&", "&E47 -> Nguyễn Văn Mười - Ấp Bình Thạnh 3, Xã Thạnh Trị | S47: =IF(OR(I47="Tôm chân trắng nhỏ",I47="Tôm sú nhỏ"),0.5,IF(OR(I47="Cá tra nhỏ",I47="Tôm sú thương phẩm",I47="Tôm chân trắng thương phẩm",I47="Tôm sú quảng canh",I47="Nước ương tôm giống"),1,IF(I47="Cá tra thương phẩm",1.5,0))) -> 1 | T47: =IFERROR(VLOOKUP(J47,'List+TK'!$D$3:$E$1000,2,0),"-") -> Ormetoprim | U47: =H47&"/"&IF(LEN(G47)=1,"0"&G47,G47)&"/2024" -> 09/04/2024 | V47: =IFERROR(VLOOKUP(K47,'List+TK'!$G$3:$H$16,2,0),"-") -> Cao Quang Nguyên | W47: =IF(N47="","",IF(I47="Nước ương tôm giống","Bể "&N47,"Ao "&N47)) -> Ao 2
A48: =_xlfn.AGGREGATE(3,3,$I$4:I48) -> 45 | B48: 6 | C48: Công ty CP Gò Đàng | D48: Ấp Hưng Thạnh | E48: Xã Châu Hưng | F48: Huyện Bình Đại | G48: 4 | H48: 09 | I48: Cá tra thương phẩm | J48: MG+LMG | K48: Nguyên | L48: =IFERROR(IF(F48="Huyện Mỏ Cày Nam","Mỏ Cày",RIGHT(F48,LEN(F48)-6)),"-") -> Bình Đại | M48: =IFERROR(VLOOKUP(L48,'List+TK'!$I$3:$J$9,2,0),"-") -> 83/02 | N48: 1 | O48: =I48 -> Cá tra thương phẩm | P48: ="83/"&IF(LEN(G48)=1,"0"&G48,G48)&"24/"&IF(LEN(B48)=1,"0"&B48,B48) -> 83/0424/06 | Q48: =L48&" "&M48 -> Bình Đại 83/02 | R48: =C48&" - "&D48&", "&E48 -> Công ty CP Gò Đàng - Ấp Hưng Thạnh, Xã Châu Hưng | S48: =IF(OR(I48="Tôm chân trắng nhỏ",I48="Tôm sú nhỏ"),0.5,IF(OR(I48="Cá tra nhỏ",I48="Tôm sú thương phẩm",I48="Tôm chân trắng thương phẩm",I48="Tôm sú quảng canh",I48="Nước ương tôm giống"),1,IF(I48="Cá tra thương phẩm",1.5,0))) -> 1.5 | T48: =IFERROR(VLOOKUP(J48,'List+TK'!$D$3:$E$1000,2,0),"-") -> Malachite Green, Leuco Malachite Green | U48: =H48&"/"&IF(LEN(G48)=1,"0"&G48,G48)&"/2024" -> 09/04/2024 | V48: =IFERROR(VLOOKUP(K48,'List+TK'!$G$3:$H$16,2,0),"-") -> Cao Quang Nguyên | W48: =IF(N48="","",IF(I48="Nước ương tôm giống","Bể "&N48,"Ao "&N48)) -> Ao 1
...

Sheet CS
A2: STT | B2: Tên cơ sở | C2: Người đại diện | D2: Địa chỉ | E2: Điện thoại | G2: Ghi chú
A3: =_xlfn.AGGREGATE(3,3,$B$4:B4) -> 1 | B3: Công ty CP Gò Đàng | D3: Lô 25, KCN Mỹ Tho, xã Trung An, TP. Mỹ Tho,
A4: =_xlfn.AGGREGATE(3,3,$B$4:B5) -> 2 | B4: Công ty TNHH CBTPXK Vạn Đức Tiền Giang | D4: Ấp Đông Hòa, xã Song Thuận, huyện Châu Thành, tỉnh Tiền Giang - Chuyển vùng nuôi ở Bến Tre.
A5: =_xlfn.AGGREGATE(3,3,$B$3:B5) -> 3 | B5: Công ty CP Vĩnh Hoàn | D5: Đường số 30, Phường 11, Tp. Cao Lãnh, tỉnh Đồng Tháp
A6: =_xlfn.AGGREGATE(3,3,$B$3:B6) -> 4 | B6: Công ty CPTS Hải Hương | D6: Lô A8-A9, KCN An Hiệp, huyện Châu Thành, Bến Tre. | E6: 02753626666
A7: =_xlfn.AGGREGATE(3,3,$B$3:B7) -> 5 | B7: Công ty CP XNK Thủy sản Bến Tre (DL 22) | D7: Ấp 9, xã Tân Thạch, huyện Châu Thành, tỉnh Bến Tre.
A8: =_xlfn.AGGREGATE(3,3,$B$3:B8) -> 6 | B8: Công ty CPTS Ngọc Xuân | D8: Ấp Đông Hòa, xã Song Thuận, huyện Châu Thành, tỉnh Tiền Giang | E8: 0909323999 Chị Thu
A9: =_xlfn.AGGREGATE(3,3,$B$3:B9) -> 7 | B9: Trại nuôi cá tra Thành Hưng | D9: Khu nuôi cá tra thương phẩm - Ấp Phú Tân, xã Phú Túc, huyện Châu Thành, tỉnh Bến Tre. | E9: 02753600609
A10: =_xlfn.AGGREGATE(3,3,$B$3:B10) -> 8 | B10: Lê Hoàng Đạt | D10: 49 Công Lý, Khu phố 2, Thị trấn Mỏ Cày Nam, huyện Mỏ Cày Nam, tỉnh Bến Tre. | E10: 0918262660
A11: =_xlfn.AGGREGATE(3,3,$B$3:B11) -> 9 | B11: Khu nuôi cá tra - Công ty CP thủy hải sản An Phú | D11: Ấp Phú Bình, Vĩnh Bình, Chợ Lách, Bến Tre
A12: =_xlfn.AGGREGATE(3,3,$B$3:B12) -> 10 | B12: Công ty CP Thủy sản Vinh Quang | D12: Lô 37 - 40 KCN Mỹ Tho - Tiền Giang
A13: =_xlfn.AGGREGATE(3,3,$B$3:B13) -> 11 | B13: Công ty CP Hùng Vương | D13: Lô 44, Khu công nghiệp Mỹ Tho, TP. Mỹ Tho, tỉnh Tiền Giang
A14: =_xlfn.AGGREGATE(3,3,$B$3:B14) -> 12 | B14: Công ty CP NTTS Hùng Vương - Miền Tây | D14: Lô 46, Khu công nghiệp Mỹ Tho, tỉnh Tiền Giang
A15: =_xlfn.AGGREGATE(3,3,$B$3:B15) -> 13 | B15: Không có mẫu
A16: =_xlfn.AGGREGATE(3,3,$B$3:B16) -> 14 | B16: Nguyễn Văn Út | D16: Ấp 7, thị trấn Tiệm Tôm, huyện Ba Tri, tỉnh Bến Tre
A17: =_xlfn.AGGREGATE(3,3,$B$3:B17) -> 15 | B17: Cao Thị Ngọc Điệp | D17: Ấp 3, xã Phú Vang, huyện Bình Đại, tỉnh Bến Tre
A18: =_xlfn.AGGREGATE(3,3,$B$3:B18) -> 16 | B18: Cao Văn Dước | D18: Ấp 3, xã Phú Vang, huyện Bình Đại, tỉnh Bến Tre
A19: =_xlfn.AGGREGATE(3,3,$B$3:B19) -> 17 | B19: Cao Văn Tùng | D19: Ấp An Hòa, xã An Nhơn, huyện Thạnh Phú, tỉnh Bến Tre
A20: =_xlfn.AGGREGATE(3,3,$B$3:B20) -> 18 | B20: Trần Văn Dũng | D20: Ấp 7, xã An Thủy, huyện Ba Tri, tỉnh Bến Tre
A21: =_xlfn.AGGREGATE(3,3,$B$3:B21) -> 19 | B21: Lê Quốc Cường | D21: Ấp Tân An, xã Thạnh Phước, huyện Bình Đại, tỉnh Bến Tre
A22: =_xlfn.AGGREGATE(3,3,$B$3:B22) -> 20 | B22: Lê Minh Khách | D22: Ấp Phước Hòa, xã Thạnh Phước, huyện Bình Đại, tỉnh Bến Tre
A23: =_xlfn.AGGREGATE(3,3,$B$3:B23) -> 21 | B23: Phạm Văn Công | D23: Ấp 1, xã Giao Thạnh, huyện Thạnh Phú, tỉnh Bến Tre
A24: =_xlfn.AGGREGATE(3,3,$B$3:B24) -> 22 | B24: Nguyễn Văn Bé Hai | D24: Ấp 8, xã An Thủy, huyện Ba Tri, tỉnh Bến Tre
A25: =_xlfn.AGGREGATE(3,3,$B$3:B25) -> 23 | B25: Cao Thanh Phong | D25: Ấp 3, xã Phú Vang, huyện Bình Đại, tỉnh Bến Tre
A26: =_xlfn.AGGREGATE(3,3,$B$3:B26) -> 24 | B26: Phạm Văn Triều | D26: Ấp 4, xã Thạnh Phong, huyện Thạnh Phú, tỉnh Bến Tre
A27: =_xlfn.AGGREGATE(3,3,$B$3:B27) -> 25 | B27: Huỳnh Văn Hai | D27: Ấp 8, xã An Thủy, huyện Ba Tri, tỉnh Bến Tre
... A70: =_xlfn.AGGREGATE(3,3,$B$3:B70) -> 68 | B70: Phạm Văn Tư | D70: Ấp 8, thị trấn Tiệm Tôm, huyện Ba Tri, tỉnh Bến Tre
A71: =_xlfn.AGGREGATE(3,3,$B$3:B71) -> 69 | B71: .
A72: =_xlfn.AGGREGATE(3,3,$B$3:B72) -> 70 | B72: .
A73: =_xlfn.AGGREGATE(3,3,$B$3:B73) -> 71 | B73: .
A74: =_xlfn.AGGREGATE(3,3,$B$3:B74) -> 72 | B74: .
A75: =_xlfn.AGGREGATE(3,3,$B$3:B75) -> 73 | B75: .
A76: =_xlfn.AGGREGATE(3,3,$B$3:B76) -> 74 | B76: .
A77: =_xlfn.AGGREGATE(3,3,$B$3:B77) -> 75 | B77: .
A78: =_xlfn.AGGREGATE(3,3,$B$3:B78) -> 76 | B78: .
A79: =_xlfn.AGGREGATE(3,3,$B$3:B79) -> 77 | B79: .
A80: =_xlfn.AGGREGATE(3,3,$B$3:B80) -> 78 | B80: .
A81: =_xlfn.AGGREGATE(3,3,$B$3:B81) -> 79 | B81: .
A82: =_xlfn.AGGREGATE(3,3,$B$3:B82) -> 80 | B82: .
... A101: =_xlfn.AGGREGATE(3,3,$B$3:B101) -> 99 | B101: .

Sheet List+TK
F1: =SUM(F3:F58) -> 152
C2: Tên mẫu | D2: Chỉ tiêu | E2: Chỉ tiêu | G2: Người lấy | I2: Tên vùng | J2: Mã số | K2: Ghi chú
A3: 1 | C3: Cá tra nhỏ | D3: Toltrazuril | E3: Toltrazuril | F3: =COUNTIF(Thuysan!T:T,E3) -> 0 | G3: An | H3: Phạm Châu An | I3: Ba Tri | J3: 83/01 | K3: Không có mẫu | Y3: Huyện Ba Tri | Z3: 1 | AA3: Huyện Ba Tri | AB3: Thị trấn Ba Tri
A4: 2 | C4: Cá tra thương phẩm | D4: A1c | E4: Methyltestosterone | F4: =COUNTIF(Thuysan!T:T,E4) -> 5 | G4: Nguyên | H4: Cao Quang Nguyên | I4: Bình Đại | J4: 83/02 | Y4: Huyện Bình Đại | Z4: 2 | AA4: Huyện Ba Tri | AB4: Xã An Bình Tây
A5: 3 | C5: Tôm chân trắng nhỏ | D5: CAP | E5: Chloramphenicol | F5: =COUNTIF(Thuysan!T:T,E5) -> 12 | G5: Thuận | H5: Phạm Minh Thuận | I5: Thạnh phú | J5: 83/03 | Y5: Huyện Châu Thành | Z5: 3 | AA5: Huyện Ba Tri | AB5: Xã An Đức
A6: 4 | C6: Tôm chân trắng thương phẩm | D6: NF | E6: Nitrofurans | F6: =COUNTIF(Thuysan!T:T,E6) -> 12 | G6: Lâm | H6: Phạm Văn Lâm | I6: Mỏ Cày | J6: 83/04 | Y6: Huyện Chợ Lách | Z6: 4 | AA6: Huyện Ba Tri | AB6: Xã An Hiệp
A7: 5 | C7: Tôm sú nhỏ | D7: Nitroi | E7: Nhóm Nitroimidazoles | F7: =COUNTIF(Thuysan!T:T,E7) -> 6 | G7: Khanh | H7: Nguyễn Duy Khanh | I7: Châu Thành | J7: 83/05 | Y7: Huyện Giồng Trôm | Z7: 5 | AA7: Huyện Ba Tri | AB7: Xã An Hòa Tây
A8: 6 | C8: Tôm sú thương phẩm | D8: TC | E8: Nhóm Tetracyclines | F8: =COUNTIF(Thuysan!T:T,E8) -> 8 | G8: Dũng | H8: Nguyễn Văn Dũng | I8: Giồng Trôm | J8: 83/06 | Y8: Huyện Mỏ Cày Bắc | Z8: 6 | AA8: Huyện Ba Tri | AB8: Xã An Ngãi Tây
A9: 7 | C9: Tôm sú quảng canh | D9: SUL | E9: Nhóm Sulfonamides | F9: =COUNTIF(Thuysan!T:T,E9) -> 6 | G9: Tú | H9: Đặng Thanh Tú | I9: Chợ Lách | J9: 83/07 | Y9: Huyện Mỏ Cày Nam | Z9: 7 | AA9: Huyện Ba Tri | AB9: Xã An Ngãi Trung
A10: 8 | C10: Nước ương tôm giống | D10: QUI | E10: Nhóm Quinolones | F10: =COUNTIF(Thuysan!T:T,E10) -> 12 | G10: . | Y10: Huyện Thạnh Phú | Z10: 8 | AA10: Huyện Ba Tri | AB10: Xã An Phú Trung
A11: 9 | C11: Cá chẽm nhỏ | D11: Flor | E11: Florfenicol | F11: =COUNTIF(Thuysan!T:T,E11) -> 5 | G11: .. | Y11: Thành phố Bến Tre | Z11: 9 | AA11: Huyện Ba Tri | AB11: Xã An Thủy
A12: 10 | C12: Cá chẽm thương phẩm | D12: Trim | E12: Trimethoprim | F12: =COUNTIF(Thuysan!T:T,E12) -> 6 | G12: … | Z12: 10 | AA12: Huyện Ba Tri | AB12: Xã Bảo Thạnh
A13: 11 | C13: … | D13: Orme | E13: Ormetoprim | F13: =COUNTIF(Thuysan!T:T,E13) -> 7 | G13: …. | Z13: 11 | AA13: Huyện Ba Tri | AB13: Xã Bảo Thuận
A14: 12 | C14: …. | D14: Fosfo | E14: Fosfomycin | F14: =COUNTIF(Thuysan!T:T,E14) -> 5 | Z14: 12 | AA14: Huyện Ba Tri | AB14: Xã Mỹ Chánh
A15: 13 | C15: ….. | D15: Eryth | E15: Erythromycin | F15: =COUNTIF(Thuysan!T:T,E15) -> 3 | Z15: 13 | AA15: Huyện Ba Tri | AB15: Xã Mỹ Hòa
A16: 14 | D16: Azadi | E16: Azadirachtin | F16: =COUNTIF(Thuysan!T:T,E16) -> 4 | Z16: 14 | AA16: Huyện Ba Tri | AB16: Xã Mỹ Nhơn
A17: 15 | D17: Amox | E17: Amoxicillin | F17: =COUNTIF(Thuysan!T:T,E17) -> 3 | Z17: 15 | AA17: Huyện Ba Tri | AB17: Xã Mỹ Thạnh
A18: 16 | D18: Iver | E18: Ivermectin | F18: =COUNTIF(Thuysan!T:T,E18) -> 2 | Z18: 16 | AA18: Huyện Ba Tri | AB18: Xã Phú Lễ
A19: 17 | D19: Trif | E19: Trifluralin | F19: =COUNTIF(Thuysan!T:T,E19) -> 4 | Z19: 17 | AA19: Huyện Ba Tri | AB19: Xã Phú Ngãi
A20: 18 | D20: Levami | E20: Levamisol | F20: =COUNTIF(Thuysan!T:T,E20) -> 2 | Z20: 18 | AA20: Huyện Ba Tri | AB20: Xã Phước Tuy
A21: 19 | D21: Fenben | E21: Fenbendazole | F21: =COUNTIF(Thuysan!T:T,E21) -> 2 | Z21: 19 | AA21: Huyện Ba Tri | AB21: Xã Tân Hưng
A22: 20 | D22: Thuốc BVTV | E22: Thuốc trừ sâu gốc Chlor hữu cơ; phospho hữu cơ; cúc tổng hợp… | F22: =COUNTIF(Thuysan!T:T,E22) -> 5 | Z22: 20 | AA22: Huyện Ba Tri | AB22: Xã Tân Mỹ
A23: 21 | D23: Fipronil | E23: Fipronil | F23: =COUNTIF(Thuysan!T:T,E23) -> 0 | Z23: 21 | AA23: Huyện Ba Tri | AB23: Xã Tân Thủy
A24: 22 | D24: KLN | E24: Pb, Hg, Cd | F24: =COUNTIF(Thuysan!T:T,E24) -> 9 | Z24: 22 | AA24: Huyện Ba Tri | AB24: Xã Tân Xuân
A25: 23 | D25: CV+LCV | E25: Crystal Violet, Leuco Crystal Violet | F25: =COUNTIF(Thuysan!T:T,E25) -> 2 | Z25: 23 | AA25: Huyện Ba Tri | AB25: Xã Vĩnh An
A26: 24 | D26: MG+LMG | E26: Malachite Green, Leuco Malachite Green | F26: =COUNTIF(Thuysan!T:T,E26) -> 3 | Z26: 24 | AA26: Huyện Ba Tri | AB26: Xã Vĩnh Hòa
A27: 25 | D27: Aver | E27: Avermectin B1a (Abarmectin B1a) | F27: =COUNTIF(Thuysan!T:T,E27) -> 1 | Z27: 1 | AA27: Huyện Bình Đại | AB27: Thị trấn Bình Đại
... A43: 41 | D43: Levami+Fenben | E43: Levamisol, Fenbendazole | F43: =COUNTIF(Thuysan!T:T,E43) -> 0 | Z43: 17 | AA43: Huyện Bình Đại | AB43: Xã Thới Thuận
A44: 42 | D44: ….. | F44: =COUNTIF(Thuysan!T:T,E44) -> 0 | Z44: 18 | AA44: Huyện Bình Đại | AB44: Xã Thừa Đức
A45: 43 | D45: B2a+B3e cá | E45: Ivermectin, Praziquantel, Trichlorfon, Avermectin B1a, Malachite Green, Leuco Malachite Green, Crystal Violet, Leuco Crystal Violet | Z45: 19 | AA45: Huyện Bình Đại | AB45: Xã Vang Quới Đông
A46: 44 | D46: NF sú QC | E46: AOZ | Z46: 20 | AA46: Huyện Bình Đại | AB46: Xã Vang Quới Tây
A47: 45 | D47: Trif+B3c | E47: Trifluralin, Pb, Hg, Cd | Z47: 1 | AA47: Huyện Châu Thành | AB47: Thị trấn Châu Thành
A48: 46 | D48: QUI+B3c | E48: Nhóm Quinolones, Pb, Hg, Cd | Z48: 2 | AA48: Huyện Châu Thành | AB48: Xã An Hiệp
A49: 47 | D49: Orme+B3c | E49: Ormetoprim, Pb, Hg, Cd | Z49: 3 | AA49: Huyện Châu Thành | AB49: Xã An Hóa
A50: 48 | D50: B3b+Fipronil+B3c | E50: Chlorpyrifos, Fipronil, Pb, Hg, Cd | Z50: 4 | AA50: Huyện Châu Thành | AB50: Xã An Khánh
A51: 49 | D51: B3e cá+B3c | E51: Malachite Green, Leuco Malachite Green, Crystal Violet, Leuco Crystal Violet, Pb, Hg, Cd | Z51: 5 | AA51: Huyện Châu Thành | AB51: Xã An Phước
A52: 50 | D52: B2a+B3c | E52: Ivermectin, Praziquantel, Trichlorfon, Avermectin B1a, Pb, Hg, Cd | Z52: 6 | AA52: Huyện Châu Thành | AB52: Xã Giao Hòa
A53: 51 | D53: Fosfo+B3c | E53: Fosfomycin, Pb, Hg, Cd | Z53: 7 | AA53: Huyện Châu Thành | AB53: Xã Giao Long
A54: 52 | D54: Eryth+B3c | E54: Erythromycin, Pb, Hg, Cd | Z54: 8 | AA54: Huyện Châu Thành | AB54: Xã Hữu Định
A55: 53 | D55: NF+B3c | E55: Nitrofurans, Pb, Hg, Cd | Z55: 9 | AA55: Huyện Châu Thành | AB55: Xã Phú An Hòa
...

Sheet T12.QD 
A1: PHỤ LỤC
A2: LẤY MẪU GIÁM SÁT DƯ LƯỢNG TỈNH BẾN TRE THÁNG 12/2022
A3: (Kèm theo Quyết định số …… /QĐ-QLCL ngày …… tháng …… năm 2022 của Chi cục Quản lý chất lượng Nông lâm sản và Thủy sản)
A5: TT | B5: Tên mẫu | C5: Mã số mẫu | D5: Mã số vùng nuôi | E5: Địa điểm lấy mẫu | F5: Khối lượng mẫu (kg) | G5: Chỉ tiêu phân tích | H5: Thời gian lấy mẫu | I5: Người lấy mẫu | J5: Ghi chú
A6: =_xlfn.AGGREGATE(3,3,$C$6:C6) -> 1 | B6: =Thuysan!O197 -> Tôm chân trắng thương phẩm | C6: =Thuysan!P197 -> 83/1222/01 | D6: =Thuysan!Q197 -> Ba Tri 83/01 | E6: =Thuysan!R197 -> Phạm Văn Ba - Ấp 7, Xã An Thủy | F6: =Thuysan!S197 -> 1 | G6: =Thuysan!T197 -> Chloramphenicol, Nhóm Quinolones | H6: =Thuysan!U197 -> 13/12/2022 | I6: =Thuysan!V197 -> Phạm Minh Thuận | J6: =Thuysan!W197 -> Ao 1
A7: =_xlfn.AGGREGATE(3,3,$C$6:C7) -> 2 | B7: =Thuysan!O198 -> Tôm chân trắng thương phẩm | C7: =Thuysan!P198 -> 83/1222/02 | E7: =Thuysan!R198 -> Phạm Văn Ba - Ấp 7, Xã An Thủy | F7: =Thuysan!S198 -> 1 | G7: =Thuysan!T198 -> Thuốc trừ sâu gốc Chlor hữu cơ, Pb, Hg, Cd | J7: =Thuysan!W198 -> Ao 2
A8: =_xlfn.AGGREGATE(3,3,$C$6:C8) -> 3 | B8: =Thuysan!O199 -> Tôm chân trắng thương phẩm | C8: =Thuysan!P199 -> 83/1222/03 | D8: =Thuysan!Q199 -> Bình Đại 83/02 | E8: =Thuysan!R199 -> Võ Huỳnh Tiến Nghĩa - Ấp 4, Xã Bình Thới | F8: =Thuysan!S199 -> 1 | G8: =Thuysan!T199 -> Chloramphenicol, Nhóm Quinolones | H8: =Thuysan!U199 -> 13/12/2022 | I8: =Thuysan!V199 -> Cao Quang Nguyên | J8: =Thuysan!W199 -> Ao 1
A9: =_xlfn.AGGREGATE(3,3,$C$6:C9) -> 4 | B9: =Thuysan!O200 -> Tôm chân trắng thương phẩm | C9: =Thuysan!P200 -> 83/1222/04 | E9: =Thuysan!R200 -> Võ Huỳnh Tiến Nghĩa - Ấp 4, Xã Bình Thới | F9: =Thuysan!S200 -> 1 | G9: =Thuysan!T200 -> Thuốc trừ sâu gốc Chlor hữu cơ, Pb, Hg, Cd | J9: =Thuysan!W200 -> Ao 2
A10: =_xlfn.AGGREGATE(3,3,$C$6:C10) -> 5 | B10: =Thuysan!O201 -> Tôm chân trắng thương phẩm | C10: =Thuysan!P201 -> 83/1222/05 | D10: =Thuysan!Q201 -> Thạnh Phú 83/03 | E10: =Thuysan!R201 -> Trần Văn Tần - Ấp Thạnh Thới B, Xã Thạnh Hải | F10: =Thuysan!S201 -> 1 | G10: =Thuysan!T201 -> Chloramphenicol, Nhóm Quinolones | H10: =Thuysan!U201 -> 14/12/2022 | J10: =Thuysan!W201 -> Ao 1
A11: =_xlfn.AGGREGATE(3,3,$C$6:C11) -> 6 | B11: =Thuysan!O202 -> Tôm chân trắng thương phẩm | C11: =Thuysan!P202 -> 83/1222/06 | E11: =Thuysan!R202 -> Trần Văn Tần - Ấp Thạnh Thới B, Xã Thạnh Hải | F11: =Thuysan!S202 -> 1 | G11: =Thuysan!T202 -> Thuốc trừ sâu gốc Chlor hữu cơ, Pb, Hg, Cd | J11: =Thuysan!W202 -> Ao 2
A12: =_xlfn.AGGREGATE(3,3,$C$6:C12) -> 7 | B12: =Thuysan!O203 -> Cá tra thương phẩm | C12: =Thuysan!P203 -> 83/1222/07 | D12: =Thuysan!Q203 -> Châu Thành 83/05 | E12: =Thuysan!R203 -> Công ty CP Gò Đàng - ấp Tân Tây, Xã Tân Phú | F12: =Thuysan!S203 -> 1.5 | G12: =Thuysan!T203 -> Chloramphenicol, Nhóm Quinolones | H12: =Thuysan!U203 -> 13/12/2022 | I12: =Thuysan!V203 -> Phạm Châu An | J12: =Thuysan!W203 -> Ao 4
A13: =_xlfn.AGGREGATE(3,3,$C$6:C13) -> 8 | B13: =Thuysan!O204 -> Cá tra thương phẩm | C13: =Thuysan!P204 -> 83/1222/08 | E13: =Thuysan!R204 -> Công ty CP Gò Đàng - ấp Tân Tây, Xã Tân Phú | F13: =Thuysan!S204 -> 1.5 | G13: =Thuysan!T204 -> Ivermectin, Praziquantel, Trichlorfon, Avermectin B1a, Malachite Green, Leuco Malachite Green, Crystal Violet, Leuco Crystal Violet | J13: =Thuysan!W204 -> Ao 5
A14: =_xlfn.AGGREGATE(3,3,$C$6:C14) -> 9 | B14: =Thuysan!O205 -> Cá tra thương phẩm | C14: =Thuysan!P205 -> 83/1222/09 | D14: =Thuysan!Q205 -> Giồng Trôm 83/06 | E14: =Thuysan!R205 -> Công ty CP Gò Đàng - Ấp 8, Xã Phước Long | F14: =Thuysan!S205 -> 1.5 | G14: =Thuysan!T205 -> Chloramphenicol, Nhóm Quinolones | H14: =Thuysan!U205 -> 14/12/2022 | I14: =Thuysan!V205 -> Phạm Minh Thuận | J14: =Thuysan!W205 -> Ao 1
A15: =_xlfn.AGGREGATE(3,3,$C$6:C15) -> 10 | B15: =Thuysan!O206 -> Cá tra thương phẩm | C15: =Thuysan!P206 -> 83/1222/10 | E15: =Thuysan!R206 -> Công ty CP Gò Đàng - Ấp 8, Xã Phước Long | F15: =Thuysan!S206 -> 1.5 | G15: =Thuysan!T206 -> - | J15: =Thuysan!W206 -> Ao 2
A16: =_xlfn.AGGREGATE(3,3,$C$6:C16) -> 11 | B16: =Thuysan!O207 -> Cá tra thương phẩm | C16: =Thuysan!P207 -> 83/1222/11 | E16: =Thuysan!R207 -> Công ty CP Gò Đàng - Ấp 8, Xã Phước Long | F16: =Thuysan!S207 -> 1.5 | G16: =Thuysan!T207 -> - | J16: =Thuysan!W207 -> Ao 5
A17: =_xlfn.AGGREGATE(3,3,$C$6:C17) -> 12 | B17: =Thuysan!O208 -> Cá tra thương phẩm | C17: =Thuysan!P208 -> 83/1222/12 | D17: =Thuysan!Q208 -> Chợ Lách 83/07 | E17: =Thuysan!R208 -> Công ty TNHH CBTPXK Vạn Đức Tiền Giang - ấp Phú Bình, Xã Vĩnh Bình | F17: =Thuysan!S208 -> 1.5 | G17: =Thuysan!T208 -> - | H17: =Thuysan!U208 -> 14/12/2022 | I17: =Thuysan!V208 -> Phạm Châu An | J17: =Thuysan!W208 -> Ao 20
A18: =_xlfn.AGGREGATE(3,3,$C$6:C18) -> 13 | B18: =Thuysan!O209 -> Cá tra thương phẩm | C18: =Thuysan!P209 -> 83/1222/13 | E18: =Thuysan!R209 -> Công ty TNHH CBTPXK Vạn Đức Tiền Giang - ấp Bình An, Xã Hòa Nghĩa | F18: =Thuysan!S209 -> 1.5 | G18: =Thuysan!T209 -> Nhóm Quinolones, Ivermectin, Praziquantel, Trichlorfon, Avermectin B1a | J18: =Thuysan!W209 -> Ao 13
